Workbook

Sheet READ ME
B1: This template is designed to get you started in your import to coinledger
B2: As we do not know your circumstances or the tax advice that you have received please modify it to suit your circumstances
B3: all income is classified as Income (could be miner or staker dividends)
B4: The Taostats_CSV transaction Type of Fee will be imported as Merchant Payment - once Imported it will need
B5: fee | C5: Merchant Payment
B7: Any extrinsic that has more than one credit, one debit and a "fee" must be manually changed (e.g. batch or portfolio rebalance)
B8: You will also have to work with Coinledger to work out how to get the cost basis for income received in each subnet (as at 2026-03-08)
A10: Instructions:
A11: 1 | B11: Copy paste the contents of every csv into the Taostats_CSV tab
A12: 2 | B12: Make sure that the additional columns after blank in the Taostats_CSV column are copied down to match the number of rows imported
C13: The Sort Order is optional - It reorders to increasing block order
C14: The Lookup Helper is not optional - it is necessary for the tab website_csv(pro) to work
A15: 3 | B15: Optional Sort Taostats_CSV using the Sort Order
A16: 4 | B16: On the website_csv(pro) - Copy the 2nd row down on the sheet for as many rows are you have in the Taostats_CSV
A17: 5 | B17: Filter the rows using Check Row (column T) for any TRUE and correct the error in the Taostats_CSV tab
A18: 6 | B18: Filter Rows using Import Row = TRUE for the rows to be imported
A19: 7 | B19: on website_csv(pro) Check the Column AG and AH for error highlight - must be zero or the maths is wrong somewhere
A20: 8 | B20: on website_csv(pro) copy the values from column titles Date through to Tag to a csv file (the other columns can be copies - they will be ignored as the column title does not match)
A22: Method to import Batches
A23: 1 | B23: Filter the Taostats_CSV sheet using Count of extrinsic >3 (most batches)
A24: 2 | B24: Search for the extrinsic on Taostats
C25: Using the StakeRemoved Event will point you towards the correct match - but be aware you might have to sum some of them
A26: 3 | B26: Manually join the two sides of the transaction together by appending to the Extrinsic-ID a letter or number e.g. 5013009-0009 -> 5013009-0009-A
A27: 4 | B27: The website_csv(pro) tab will merge the transactions together for you - see example below
A29: Notes:
A30: 1 | B30: Each Taostats_CSV includes the opening balance - this is for verification purposes with accounting software balance - this row is usually not imported
A31: 2 | B31: Again a warning - batch transactions you have to work it out yourself
A32: 3 | B32: Again a warning - After a CoinLedger import you must review the transactions and ensure that the cost basis is correct
A34: valid tags for CoinLedger
A35: source for types | B35: https://help.coinledger.io/en/articles/8546372-what-transaction-types-does-coinledger-support
A36: import instructions | B36: https://help.coinledger.io/en/articles/6028758-universal-manual-import-template-guide
B39: Batch
B49: is converted to website_csv(pro)

Sheet Taostats_CSV
A2: Coldkey | B2: Block number | C2: Timestamp | D2: Network | E2: Token | F2: Transaction type | G2: Debit amount | H2: Credit amount | I2: Extrinsic ID | J2: Additional data | K2: Total balance | L2: Free balance | M2: Staked balance | N2: Locked balance | O2: Reserved balance | P2: Token price in USD | Q2: Token price in TAO | R2: Daily income | S2: Daily income USD | T2: Date | U2: blank | V2: Sort Order | W2: Count of extrinsic | X2: Lookup Helper | Y2: Net Amount (for a pivot table)
A3: 5Eq8C1NoLah4DaahQLMQ6wPLTSiAoiP35kVs9VMjaEqcSmdF | B3: 4605427 | C3: 2024-12-31T23:59:48+00:00 | D3: finney | E3: TAO | K3: 256.53009 | L3: 2.6901865 | M3: 253.8399 | N3: 0 | O3: 0 | P3: 439.7119272666333 | Q3: 1 | R3: 256.53009 | V3: ="S-"&IF(LEN(I3)=0,B3,I3&IF(F3="fee","-00",IF(LEN(G3)>0,"-01","-02"))) -> S-4605427 | W3: =COUNTIF(I:I,I3) -> 0 | X3: =IF(LEN(I3)>0,I3&IF(F3="fee","fee",IF(VALUE(G3)>0,"debit",IF(VALUE(H3)>0,"credit","error"))),"") | Y3: =ROUND(IF(ROW(U3) = 2,K3,0)+IF(H3<>"",H3,0) + IF(R3<>"",R3,0) - IF(G3<>"",G3,0),9) -> 256.53009
A4: 5Eq8C1NoLah4DaahQLMQ6wPLTSiAoiP35kVs9VMjaEqcSmdF | B4: 4612627 | C4: 2025-01-01T23:59:48+00:00 | D4: finney | E4: TAO | K4: 256.66097 | L4: 2.6901865 | M4: 253.97079 | N4: 0 | O4: 0 | P4: 487.3709307352656 | Q4: 1 | R4: 0.13088539 | S4: 63.78 | T4: 45658 | V4: ="S-"&IF(LEN(I4)=0,B4,I4&IF(F4="fee","-00",IF(LEN(G4)>0,"-01","-02"))) -> S-4612627 | W4: =COUNTIF(I:I,I4) -> 0 | X4: =IF(LEN(I4)>0,I4&IF(F4="fee","fee",IF(VALUE(G4)>0,"debit",IF(VALUE(H4)>0,"credit","error"))),"") | Y4: =ROUND(IF(ROW(U4) = 2,K4,0)+IF(H4<>"",H4,0) + IF(R4<>"",R4,0) - IF(G4<>"",G4,0),9) -> 0.13088539
A5: 5Eq8C1NoLah4DaahQLMQ6wPLTSiAoiP35kVs9VMjaEqcSmdF | B5: 4619827 | C5: 2025-01-02T23:59:48+00:00 | D5: finney | E5: TAO | K5: 256.77263 | L5: 2.6901865 | M5: 254.08245 | N5: 0 | O5: 0 | P5: 522.0907380013595 | Q5: 1 | R5: 0.11166127 | S5: 58.29 | T5: 45659 | V5: ="S-"&IF(LEN(I5)=0,B5,I5&IF(F5="fee","-00",IF(LEN(G5)>0,"-01","-02"))) -> S-4619827 | W5: =COUNTIF(I:I,I5) -> 0 | X5: =IF(LEN(I5)>0,I5&IF(F5="fee","fee",IF(VALUE(G5)>0,"debit",IF(VALUE(H5)>0,"credit","error"))),"") | Y5: =ROUND(IF(ROW(U5) = 2,K5,0)+IF(H5<>"",H5,0) + IF(R5<>"",R5,0) - IF(G5<>"",G5,0),9) -> 0.11166127
A6: 5Eq8C1NoLah4DaahQLMQ6wPLTSiAoiP35kVs9VMjaEqcSmdF | B6: 4627027 | C6: 2025-01-03T23:59:48+00:00 | D6: finney | E6: TAO | K6: 256.88524 | L6: 2.6901865 | M6: 254.19506 | N6: 0 | O6: 0 | P6: 551.3484249315601 | Q6: 1 | R6: 0.1126101 | S6: 62.08 | T6: 45660 | V6: ="S-"&IF(LEN(I6)=0,B6,I6&IF(F6="fee","-00",IF(LEN(G6)>0,"-01","-02"))) -> S-4627027 | W6: =COUNTIF(I:I,I6) -> 0 | X6: =IF(LEN(I6)>0,I6&IF(F6="fee","fee",IF(VALUE(G6)>0,"debit",IF(VALUE(H6)>0,"credit","error"))),"") | Y6: =ROUND(IF(ROW(U6) = 2,K6,0)+IF(H6<>"",H6,0) + IF(R6<>"",R6,0) - IF(G6<>"",G6,0),9) -> 0.1126101
A7: 5Eq8C1NoLah4DaahQLMQ6wPLTSiAoiP35kVs9VMjaEqcSmdF | B7: 4634227 | C7: 2025-01-04T23:59:48+00:00 | D7: finney | E7: TAO | K7: 256.99636 | L7: 2.6901865 | M7: 254.30617 | N7: 0 | O7: 0 | P7: 561.8861556228987 | Q7: 1 | R7: 0.11111491 | S7: 62.43 | T7: 45661 | V7: ="S-"&IF(LEN(I7)=0,B7,I7&IF(F7="fee","-00",IF(LEN(G7)>0,"-01","-02"))) -> S-4634227 | W7: =COUNTIF(I:I,I7) -> 0 | X7: =IF(LEN(I7)>0,I7&IF(F7="fee","fee",IF(VALUE(G7)>0,"debit",IF(VALUE(H7)>0,"credit","error"))),"") | Y7: =ROUND(IF(ROW(U7) = 2,K7,0)+IF(H7<>"",H7,0) + IF(R7<>"",R7,0) - IF(G7<>"",G7,0),9) -> 0.11111491
A8: 5Eq8C1NoLah4DaahQLMQ6wPLTSiAoiP35kVs9VMjaEqcSmdF | B8: 4641427 | C8: 2025-01-05T23:59:48+00:00 | D8: finney | E8: TAO | K8: 257.109 | L8: 2.6901865 | M8: 254.41881 | N8: 0 | O8: 0 | P8: 566.19555 | Q8: 1 | R8: 0.11264267 | S8: 63.77 | T8: 45662 | V8: ="S-"&IF(LEN(I8)=0,B8,I8&IF(F8="fee","-00",IF(LEN(G8)>0,"-01","-02"))) -> S-4641427 | W8: =COUNTIF(I:I,I8) -> 0 | X8: =IF(LEN(I8)>0,I8&IF(F8="fee","fee",IF(VALUE(G8)>0,"debit",IF(VALUE(H8)>0,"credit","error"))),"") | Y8: =ROUND(IF(ROW(U8) = 2,K8,0)+IF(H8<>"",H8,0) + IF(R8<>"",R8,0) - IF(G8<>"",G8,0),9) -> 0.11264267
A9: 5Eq8C1NoLah4DaahQLMQ6wPLTSiAoiP35kVs9VMjaEqcSmdF | B9: 4648627 | C9: 2025-01-06T23:59:48+00:00 | D9: finney | E9: TAO | K9: 257.22522 | L9: 2.6901865 | M9: 254.53503 | N9: 0 | O9: 0 | P9: 555.4454806317118 | Q9: 1 | R9: 0.11621987 | S9: 64.55 | T9: 45663 | V9: ="S-"&IF(LEN(I9)=0,B9,I9&IF(F9="fee","-00",IF(LEN(G9)>0,"-01","-02"))) -> S-4648627 | W9: =COUNTIF(I:I,I9) -> 0 | X9: =IF(LEN(I9)>0,I9&IF(F9="fee","fee",IF(VALUE(G9)>0,"debit",IF(VALUE(H9)>0,"credit","error"))),"") | Y9: =ROUND(IF(ROW(U9) = 2,K9,0)+IF(H9<>"",H9,0) + IF(R9<>"",R9,0) - IF(G9<>"",G9,0),9) -> 0.11621987
A10: 5Eq8C1NoLah4DaahQLMQ6wPLTSiAoiP35kVs9VMjaEqcSmdF | B10: 4655827 | C10: 2025-01-07T23:59:48+00:00 | D10: finney | E10: TAO | K10: 257.34256 | L10: 2.6901865 | M10: 254.65237 | N10: 0 | O10: 0 | P10: 501.76673194932215 | Q10: 1 | R10: 0.11733869 | S10: 58.87 | T10: 45664 | V10: ="S-"&IF(LEN(I10)=0,B10,I10&IF(F10="fee","-00",IF(LEN(G10)>0,"-01","-02"))) -> S-4655827 | W10: =COUNTIF(I:I,I10) -> 0 | X10: =IF(LEN(I10)>0,I10&IF(F10="fee","fee",IF(VALUE(G10)>0,"debit",IF(VALUE(H10)>0,"credit","error"))),"") | Y10: =ROUND(IF(ROW(U10) = 2,K10,0)+IF(H10<>"",H10,0) + IF(R10<>"",R10,0) - IF(G10<>"",G10,0),9) -> 0.11733869
A11: 5Eq8C1NoLah4DaahQLMQ6wPLTSiAoiP35kVs9VMjaEqcSmdF | B11: 4663027 | C11: 2025-01-08T23:59:48+00:00 | D11: finney | E11: TAO | K11: 257.45859 | L11: 2.6901865 | M11: 254.76841 | N11: 0 | O11: 0 | P11: 468.2963637012752 | Q11: 1 | R11: 0.11603302 | S11: 54.33 | T11: 45665 | V11: ="S-"&IF(LEN(I11)=0,B11,I11&IF(F11="fee","-00",IF(LEN(G11)>0,"-01","-02"))) -> S-4663027 | W11: =COUNTIF(I:I,I11) -> 0 | X11: =IF(LEN(I11)>0,I11&IF(F11="fee","fee",IF(VALUE(G11)>0,"debit",IF(VALUE(H11)>0,"credit","error"))),"") | Y11: =ROUND(IF(ROW(U11) = 2,K11,0)+IF(H11<>"",H11,0) + IF(R11<>"",R11,0) - IF(G11<>"",G11,0),9) -> 0.11603302
A12: 5Eq8C1NoLah4DaahQLMQ6wPLTSiAoiP35kVs9VMjaEqcSmdF | B12: 4670227 | C12: 2025-01-09T23:59:48+00:00 | D12: finney | E12: TAO | K12: 257.56864 | L12: 2.6901865 | M12: 254.87845 | N12: 0 | O12: 0 | P12: 431.32496169673266 | Q12: 1 | R12: 0.11004859 | S12: 47.46 | T12: 45666 | V12: ="S-"&IF(LEN(I12)=0,B12,I12&IF(F12="fee","-00",IF(LEN(G12)>0,"-01","-02"))) -> S-4670227 | W12: =COUNTIF(I:I,I12) -> 0 | X12: =IF(LEN(I12)>0,I12&IF(F12="fee","fee",IF(VALUE(G12)>0,"debit",IF(VALUE(H12)>0,"credit","error"))),"") | Y12: =ROUND(IF(ROW(U12) = 2,K12,0)+IF(H12<>"",H12,0) + IF(R12<>"",R12,0) - IF(G12<>"",G12,0),9) -> 0.11004859
A13: 5Eq8C1NoLah4DaahQLMQ6wPLTSiAoiP35kVs9VMjaEqcSmdF | B13: 4677427 | C13: 2025-01-10T23:59:48+00:00 | D13: finney | E13: TAO | K13: 257.67884 | L13: 2.6901865 | M13: 254.98865 | N13: 0 | O13: 0 | P13: 440.5970263845009 | Q13: 1 | R13: 0.11019781 | S13: 48.55 | T13: 45667 | V13: ="S-"&IF(LEN(I13)=0,B13,I13&IF(F13="fee","-00",IF(LEN(G13)>0,"-01","-02"))) -> S-4677427 | W13: =COUNTIF(I:I,I13) -> 0 | X13: =IF(LEN(I13)>0,I13&IF(F13="fee","fee",IF(VALUE(G13)>0,"debit",IF(VALUE(H13)>0,"credit","error"))),"") | Y13: =ROUND(IF(ROW(U13) = 2,K13,0)+IF(H13<>"",H13,0) + IF(R13<>"",R13,0) - IF(G13<>"",G13,0),9) -> 0.11019781
A14: 5Eq8C1NoLah4DaahQLMQ6wPLTSiAoiP35kVs9VMjaEqcSmdF | B14: 4684626 | C14: 2025-01-11T23:59:48+00:00 | D14: finney | E14: TAO | K14: 257.7909 | L14: 2.6901865 | M14: 255.10071 | N14: 0 | O14: 0 | P14: 447.6506990278048 | Q14: 1 | R14: 0.11206236 | S14: 50.16 | T14: 45668 | V14: ="S-"&IF(LEN(I14)=0,B14,I14&IF(F14="fee","-00",IF(LEN(G14)>0,"-01","-02"))) -> S-4684626 | W14: =COUNTIF(I:I,I14) -> 0 | X14: =IF(LEN(I14)>0,I14&IF(F14="fee","fee",IF(VALUE(G14)>0,"debit",IF(VALUE(H14)>0,"credit","error"))),"") | Y14: =ROUND(IF(ROW(U14) = 2,K14,0)+IF(H14<>"",H14,0) + IF(R14<>"",R14,0) - IF(G14<>"",G14,0),9) -> 0.11206236
A15: 5Eq8C1NoLah4DaahQLMQ6wPLTSiAoiP35kVs9VMjaEqcSmdF | B15: 4691826 | C15: 2025-01-12T23:59:48+00:00 | D15: finney | E15: TAO | K15: 257.90264 | L15: 2.6901865 | M15: 255.21246 | N15: 0 | O15: 0 | P15: 443.41416776212833 | Q15: 1 | R15: 0.11174071 | S15: 49.54 | T15: 45669 | V15: ="S-"&IF(LEN(I15)=0,B15,I15&IF(F15="fee","-00",IF(LEN(G15)>0,"-01","-02"))) -> S-4691826 | W15: =COUNTIF(I:I,I15) -> 0 | X15: =IF(LEN(I15)>0,I15&IF(F15="fee","fee",IF(VALUE(G15)>0,"debit",IF(VALUE(H15)>0,"credit","error"))),"") | Y15: =ROUND(IF(ROW(U15) = 2,K15,0)+IF(H15<>"",H15,0) + IF(R15<>"",R15,0) - IF(G15<>"",G15,0),9) -> 0.11174071
A16: 5Eq8C1NoLah4DaahQLMQ6wPLTSiAoiP35kVs9VMjaEqcSmdF | B16: 4699026 | C16: 2025-01-13T23:59:48.001+00:00 | D16: finney | E16: TAO | K16: 258.01303 | L16: 2.6901865 | M16: 255.32285 | N16: 0 | O16: 0 | P16: 420.58693541865387 | Q16: 1 | R16: 0.11039172 | S16: 46.42 | T16: 45670 | V16: ="S-"&IF(LEN(I16)=0,B16,I16&IF(F16="fee","-00",IF(LEN(G16)>0,"-01","-02"))) -> S-4699026 | W16: =COUNTIF(I:I,I16) -> 0 | X16: =IF(LEN(I16)>0,I16&IF(F16="fee","fee",IF(VALUE(G16)>0,"debit",IF(VALUE(H16)>0,"credit","error"))),"") | Y16: =ROUND(IF(ROW(U16) = 2,K16,0)+IF(H16<>"",H16,0) + IF(R16<>"",R16,0) - IF(G16<>"",G16,0),9) -> 0.11039172
A17: 5Eq8C1NoLah4DaahQLMQ6wPLTSiAoiP35kVs9VMjaEqcSmdF | B17: 4706226 | C17: 2025-01-14T23:59:48+00:00 | D17: finney | E17: TAO | K17: 258.12203 | L17: 2.6901865 | M17: 255.43184 | N17: 0 | O17: 0 | P17: 417.21127 | Q17: 1 | R17: 0.1089928 | S17: 45.47 | T17: 45671 | V17: ="S-"&IF(LEN(I17)=0,B17,I17&IF(F17="fee","-00",IF(LEN(G17)>0,"-01","-02"))) -> S-4706226 | W17: =COUNTIF(I:I,I17) -> 0 | X17: =IF(LEN(I17)>0,I17&IF(F17="fee","fee",IF(VALUE(G17)>0,"debit",IF(VALUE(H17)>0,"credit","error"))),"") | Y17: =ROUND(IF(ROW(U17) = 2,K17,0)+IF(H17<>"",H17,0) + IF(R17<>"",R17,0) - IF(G17<>"",G17,0),9) -> 0.1089928
A18: 5Eq8C1NoLah4DaahQLMQ6wPLTSiAoiP35kVs9VMjaEqcSmdF | B18: 4713426 | C18: 2025-01-15T23:59:48+00:00 | D18: finney | E18: TAO | K18: 258.23076 | L18: 2.6901865 | M18: 255.54057 | N18: 0 | O18: 0 | P18: 457.0246357089349 | Q18: 1 | R18: 0.1087295 | S18: 49.69 | T18: 45672 | V18: ="S-"&IF(LEN(I18)=0,B18,I18&IF(F18="fee","-00",IF(LEN(G18)>0,"-01","-02"))) -> S-4713426 | W18: =COUNTIF(I:I,I18) -> 0 | X18: =IF(LEN(I18)>0,I18&IF(F18="fee","fee",IF(VALUE(G18)>0,"debit",IF(VALUE(H18)>0,"credit","error"))),"") | Y18: =ROUND(IF(ROW(U18) = 2,K18,0)+IF(H18<>"",H18,0) + IF(R18<>"",R18,0) - IF(G18<>"",G18,0),9) -> 0.1087295
A19: 5Eq8C1NoLah4DaahQLMQ6wPLTSiAoiP35kVs9VMjaEqcSmdF | B19: 4720626 | C19: 2025-01-16T23:59:48+00:00 | D19: finney | E19: TAO | K19: 258.33966 | L19: 2.6901865 | M19: 255.64948 | N19: 0 | O19: 0 | P19: 443.5276377025133 | Q19: 1 | R19: 0.10890706 | S19: 48.3 | T19: 45673 | V19: ="S-"&IF(LEN(I19)=0,B19,I19&IF(F19="fee","-00",IF(LEN(G19)>0,"-01","-02"))) -> S-4720626 | W19: =COUNTIF(I:I,I19) -> 0 | X19: =IF(LEN(I19)>0,I19&IF(F19="fee","fee",IF(VALUE(G19)>0,"debit",IF(VALUE(H19)>0,"credit","error"))),"") | Y19: =ROUND(IF(ROW(U19) = 2,K19,0)+IF(H19<>"",H19,0) + IF(R19<>"",R19,0) - IF(G19<>"",G19,0),9) -> 0.10890706
A20: 5Eq8C1NoLah4DaahQLMQ6wPLTSiAoiP35kVs9VMjaEqcSmdF | B20: 4727826 | C20: 2025-01-17T23:59:48+00:00 | D20: finney | E20: TAO | K20: 258.45136 | L20: 2.6901865 | M20: 255.76118 | N20: 0 | O20: 0 | P20: 486.9949653436108 | Q20: 1 | R20: 0.11169907 | S20: 54.39 | T20: 45674 | V20: ="S-"&IF(LEN(I20)=0,B20,I20&IF(F20="fee","-00",IF(LEN(G20)>0,"-01","-02"))) -> S-4727826 | W20: =COUNTIF(I:I,I20) -> 0 | X20: =IF(LEN(I20)>0,I20&IF(F20="fee","fee",IF(VALUE(G20)>0,"debit",IF(VALUE(H20)>0,"credit","error"))),"") | Y20: =ROUND(IF(ROW(U20) = 2,K20,0)+IF(H20<>"",H20,0) + IF(R20<>"",R20,0) - IF(G20<>"",G20,0),9) -> 0.11169907
A21: 5Eq8C1NoLah4DaahQLMQ6wPLTSiAoiP35kVs9VMjaEqcSmdF | B21: 4735025 | C21: 2025-01-18T23:59:48+00:00 | D21: finney | E21: TAO | K21: 258.5665 | L21: 2.6901865 | M21: 255.87631 | N21: 0 | O21: 0 | P21: 460.0504845163183 | Q21: 1 | R21: 0.11513431 | S21: 52.96 | T21: 45675 | V21: ="S-"&IF(LEN(I21)=0,B21,I21&IF(F21="fee","-00",IF(LEN(G21)>0,"-01","-02"))) -> S-4735025 | W21: =COUNTIF(I:I,I21) -> 0 | X21: =IF(LEN(I21)>0,I21&IF(F21="fee","fee",IF(VALUE(G21)>0,"debit",IF(VALUE(H21)>0,"credit","error"))),"") | Y21: =ROUND(IF(ROW(U21) = 2,K21,0)+IF(H21<>"",H21,0) + IF(R21<>"",R21,0) - IF(G21<>"",G21,0),9) -> 0.11513431
A22: 5Eq8C1NoLah4DaahQLMQ6wPLTSiAoiP35kVs9VMjaEqcSmdF | B22: 4742224 | C22: 2025-01-19T23:59:48+00:00 | D22: finney | E22: TAO | K22: 258.68097 | L22: 2.6901865 | M22: 255.99078 | N22: 0 | O22: 0 | P22: 424.48641007258374 | Q22: 1 | R22: 0.11447006 | S22: 48.59 | T22: 45676 | V22: ="S-"&IF(LEN(I22)=0,B22,I22&IF(F22="fee","-00",IF(LEN(G22)>0,"-01","-02"))) -> S-4742224 | W22: =COUNTIF(I:I,I22) -> 0 | X22: =IF(LEN(I22)>0,I22&IF(F22="fee","fee",IF(VALUE(G22)>0,"debit",IF(VALUE(H22)>0,"credit","error"))),"") | Y22: =ROUND(IF(ROW(U22) = 2,K22,0)+IF(H22<>"",H22,0) + IF(R22<>"",R22,0) - IF(G22<>"",G22,0),9) -> 0.11447006
A23: 5Eq8C1NoLah4DaahQLMQ6wPLTSiAoiP35kVs9VMjaEqcSmdF | B23: 4749424 | C23: 2025-01-20T23:59:48+00:00 | D23: finney | E23: TAO | K23: 258.79933 | L23: 2.6901865 | M23: 256.10914 | N23: 0 | O23: 0 | P23: 409.87366320933495 | Q23: 1 | R23: 0.11835984 | S23: 48.51 | T23: 45677 | V23: ="S-"&IF(LEN(I23)=0,B23,I23&IF(F23="fee","-00",IF(LEN(G23)>0,"-01","-02"))) -> S-4749424 | W23: =COUNTIF(I:I,I23) -> 0 | X23: =IF(LEN(I23)>0,I23&IF(F23="fee","fee",IF(VALUE(G23)>0,"debit",IF(VALUE(H23)>0,"credit","error"))),"") | Y23: =ROUND(IF(ROW(U23) = 2,K23,0)+IF(H23<>"",H23,0) + IF(R23<>"",R23,0) - IF(G23<>"",G23,0),9) -> 0.11835984
A24: 5Eq8C1NoLah4DaahQLMQ6wPLTSiAoiP35kVs9VMjaEqcSmdF | B24: 4756623 | C24: 2025-01-21T23:59:48.001+00:00 | D24: finney | E24: TAO | K24: 258.92652 | L24: 2.6901865 | M24: 256.23633 | N24: 0 | O24: 0 | P24: 426.34802246929024 | Q24: 1 | R24: 0.12719171 | S24: 54.22 | T24: 45678 | V24: ="S-"&IF(LEN(I24)=0,B24,I24&IF(F24="fee","-00",IF(LEN(G24)>0,"-01","-02"))) -> S-4756623 | W24: =COUNTIF(I:I,I24) -> 0 | X24: =IF(LEN(I24)>0,I24&IF(F24="fee","fee",IF(VALUE(G24)>0,"debit",IF(VALUE(H24)>0,"credit","error"))),"") | Y24: =ROUND(IF(ROW(U24) = 2,K24,0)+IF(H24<>"",H24,0) + IF(R24<>"",R24,0) - IF(G24<>"",G24,0),9) -> 0.12719171
A25: 5Eq8C1NoLah4DaahQLMQ6wPLTSiAoiP35kVs9VMjaEqcSmdF | B25: 4763823 | C25: 2025-01-22T23:59:48+00:00 | D25: finney | E25: TAO | K25: 259.04237 | L25: 2.6901865 | M25: 256.35218 | N25: 0 | O25: 0 | P25: 401.1287822762729 | Q25: 1 | R25: 0.11585211 | S25: 46.47 | T25: 45679 | V25: ="S-"&IF(LEN(I25)=0,B25,I25&IF(F25="fee","-00",IF(LEN(G25)>0,"-01","-02"))) -> S-4763823 | W25: =COUNTIF(I:I,I25) -> 0 | X25: =IF(LEN(I25)>0,I25&IF(F25="fee","fee",IF(VALUE(G25)>0,"debit",IF(VALUE(H25)>0,"credit","error"))),"") | Y25: =ROUND(IF(ROW(U25) = 2,K25,0)+IF(H25<>"",H25,0) + IF(R25<>"",R25,0) - IF(G25<>"",G25,0),9) -> 0.11585211
A26: 5Eq8C1NoLah4DaahQLMQ6wPLTSiAoiP35kVs9VMjaEqcSmdF | B26: 4771023 | C26: 2025-01-23T23:59:48.001+00:00 | D26: finney | E26: TAO | K26: 259.15634 | L26: 2.6901865 | M26: 256.46615 | N26: 0 | O26: 0 | P26: 380.85226745247263 | Q26: 1 | R26: 0.11396705 | S26: 43.4 | T26: 45680 | V26: ="S-"&IF(LEN(I26)=0,B26,I26&IF(F26="fee","-00",IF(LEN(G26)>0,"-01","-02"))) -> S-4771023 | W26: =COUNTIF(I:I,I26) -> 0 | X26: =IF(LEN(I26)>0,I26&IF(F26="fee","fee",IF(VALUE(G26)>0,"debit",IF(VALUE(H26)>0,"credit","error"))),"") | Y26: =ROUND(IF(ROW(U26) = 2,K26,0)+IF(H26<>"",H26,0) + IF(R26<>"",R26,0) - IF(G26<>"",G26,0),9) -> 0.11396705
A27: 5Eq8C1NoLah4DaahQLMQ6wPLTSiAoiP35kVs9VMjaEqcSmdF | B27: 4778223 | C27: 2025-01-24T23:59:48+00:00 | D27: finney | E27: TAO | K27: 259.27148 | L27: 2.6901865 | M27: 256.58129 | N27: 0 | O27: 0 | P27: 370.5888915790195 | Q27: 1 | R27: 0.11514419 | S27: 42.67 | T27: 45681 | V27: ="S-"&IF(LEN(I27)=0,B27,I27&IF(F27="fee","-00",IF(LEN(G27)>0,"-01","-02"))) -> S-4778223 | W27: =COUNTIF(I:I,I27) -> 0 | X27: =IF(LEN(I27)>0,I27&IF(F27="fee","fee",IF(VALUE(G27)>0,"debit",IF(VALUE(H27)>0,"credit","error"))),"") | Y27: =ROUND(IF(ROW(U27) = 2,K27,0)+IF(H27<>"",H27,0) + IF(R27<>"",R27,0) - IF(G27<>"",G27,0),9) -> 0.11514419
A28: 5Eq8C1NoLah4DaahQLMQ6wPLTSiAoiP35kVs9VMjaEqcSmdF | B28: 4785423 | C28: 2025-01-25T23:59:48+00:00 | D28: finney | E28: TAO | K28: 259.38862 | L28: 2.6901865 | M28: 256.69843 | N28: 0 | O28: 0 | P28: 413.19252714481706 | Q28: 1 | R28: 0.11713619 | S28: 48.39 | T28: 45682 | V28: ="S-"&IF(LEN(I28)=0,B28,I28&IF(F28="fee","-00",IF(LEN(G28)>0,"-01","-02"))) -> S-4785423 | W28: =COUNTIF(I:I,I28) -> 0 | X28: =IF(LEN(I28)>0,I28&IF(F28="fee","fee",IF(VALUE(G28)>0,"debit",IF(VALUE(H28)>0,"credit","error"))),"") | Y28: =ROUND(IF(ROW(U28) = 2,K28,0)+IF(H28<>"",H28,0) + IF(R28<>"",R28,0) - IF(G28<>"",G28,0),9) -> 0.11713619
A29: 5Eq8C1NoLah4DaahQLMQ6wPLTSiAoiP35kVs9VMjaEqcSmdF | B29: 4792622 | C29: 2025-01-26T23:59:48+00:00 | D29: finney | E29: TAO | K29: 259.5058 | L29: 2.6901865 | M29: 256.81561 | N29: 0 | O29: 0 | P29: 433.4903129911173 | Q29: 1 | R29: 0.11718267 | S29: 50.79 | T29: 45683 | V29: ="S-"&IF(LEN(I29)=0,B29,I29&IF(F29="fee","-00",IF(LEN(G29)>0,"-01","-02"))) -> S-4792622 | W29: =COUNTIF(I:I,I29) -> 0 | X29: =IF(LEN(I29)>0,I29&IF(F29="fee","fee",IF(VALUE(G29)>0,"debit",IF(VALUE(H29)>0,"credit","error"))),"") | Y29: =ROUND(IF(ROW(U29) = 2,K29,0)+IF(H29<>"",H29,0) + IF(R29<>"",R29,0) - IF(G29<>"",G29,0),9) -> 0.11718267
... A31: 5Eq8C1NoLah4DaahQLMQ6wPLTSiAoiP35kVs9VMjaEqcSmdF | B31: 4807022 | C31: 2025-01-28T23:59:48+00:00 | D31: finney | E31: TAO | K31: 259.74492 | L31: 2.6901865 | M31: 257.05473 | N31: 0 | O31: 0 | P31: 444.90636618436974 | Q31: 1 | R31: 0.11970531 | S31: 53.25 | T31: 45685 | V31: ="S-"&IF(LEN(I31)=0,B31,I31&IF(F31="fee","-00",IF(LEN(G31)>0,"-01","-02"))) -> S-4807022 | W31: =COUNTIF(I:I,I31) -> 0 | X31: =IF(LEN(I31)>0,I31&IF(F31="fee","fee",IF(VALUE(G31)>0,"debit",IF(VALUE(H31)>0,"credit","error"))),"") | Y31: =ROUND(IF(ROW(U31) = 2,K31,0)+IF(H31<>"",H31,0) + IF(R31<>"",R31,0) - IF(G31<>"",G31,0),9) -> 0.11970531
A32: 5Eq8C1NoLah4DaahQLMQ6wPLTSiAoiP35kVs9VMjaEqcSmdF | B32: 4814222 | C32: 2025-01-29T23:59:48.001+00:00 | D32: finney | E32: TAO | K32: 259.85818 | L32: 2.6901865 | M32: 257.16799 | N32: 0 | O32: 0 | P32: 450.68657 | Q32: 1 | R32: 0.11325916 | S32: 51.04 | T32: 45686 | V32: ="S-"&IF(LEN(I32)=0,B32,I32&IF(F32="fee","-00",IF(LEN(G32)>0,"-01","-02"))) -> S-4814222 | W32: =COUNTIF(I:I,I32) -> 0 | X32: =IF(LEN(I32)>0,I32&IF(F32="fee","fee",IF(VALUE(G32)>0,"debit",IF(VALUE(H32)>0,"credit","error"))),"") | Y32: =ROUND(IF(ROW(U32) = 2,K32,0)+IF(H32<>"",H32,0) + IF(R32<>"",R32,0) - IF(G32<>"",G32,0),9) -> 0.11325916
A33: 5Eq8C1NoLah4DaahQLMQ6wPLTSiAoiP35kVs9VMjaEqcSmdF | B33: 4821422 | C33: 2025-01-30T23:59:48+00:00 | D33: finney | E33: TAO | K33: 259.97457 | L33: 2.6901865 | M33: 257.28438 | N33: 0 | O33: 0 | P33: 454.5244163596316 | Q33: 1 | R33: 0.11638804 | S33: 52.9 | T33: 45687 | V33: ="S-"&IF(LEN(I33)=0,B33,I33&IF(F33="fee","-00",IF(LEN(G33)>0,"-01","-02"))) -> S-4821422 | W33: =COUNTIF(I:I,I33) -> 0 | X33: =IF(LEN(I33)>0,I33&IF(F33="fee","fee",IF(VALUE(G33)>0,"debit",IF(VALUE(H33)>0,"credit","error"))),"") | Y33: =ROUND(IF(ROW(U33) = 2,K33,0)+IF(H33<>"",H33,0) + IF(R33<>"",R33,0) - IF(G33<>"",G33,0),9) -> 0.11638804
A34: 5Eq8C1NoLah4DaahQLMQ6wPLTSiAoiP35kVs9VMjaEqcSmdF | B34: 4828622 | C34: 2025-01-31T23:59:48.001+00:00 | D34: finney | E34: TAO | K34: 260.09391 | L34: 2.6901865 | M34: 257.40372 | N34: 0 | O34: 0 | P34: 448.76411187910935 | Q34: 1 | R34: 0.11934045 | S34: 53.55 | T34: 45688 | V34: ="S-"&IF(LEN(I34)=0,B34,I34&IF(F34="fee","-00",IF(LEN(G34)>0,"-01","-02"))) -> S-4828622 | W34: =COUNTIF(I:I,I34) -> 0 | X34: =IF(LEN(I34)>0,I34&IF(F34="fee","fee",IF(VALUE(G34)>0,"debit",IF(VALUE(H34)>0,"credit","error"))),"") | Y34: =ROUND(IF(ROW(U34) = 2,K34,0)+IF(H34<>"",H34,0) + IF(R34<>"",R34,0) - IF(G34<>"",G34,0),9) -> 0.11934045
A35: 5Eq8C1NoLah4DaahQLMQ6wPLTSiAoiP35kVs9VMjaEqcSmdF | B35: 4835821 | C35: 2025-02-01T23:59:48.001+00:00 | D35: finney | E35: TAO | K35: 260.21314 | L35: 2.6901865 | M35: 257.52295 | N35: 0 | O35: 0 | P35: 395.1650880030533 | Q35: 1 | R35: 0.11922854 | S35: 47.11 | T35: 45689 | V35: ="S-"&IF(LEN(I35)=0,B35,I35&IF(F35="fee","-00",IF(LEN(G35)>0,"-01","-02"))) -> S-4835821 | W35: =COUNTIF(I:I,I35) -> 0 | X35: =IF(LEN(I35)>0,I35&IF(F35="fee","fee",IF(VALUE(G35)>0,"debit",IF(VALUE(H35)>0,"credit","error"))),"") | Y35: =ROUND(IF(ROW(U35) = 2,K35,0)+IF(H35<>"",H35,0) + IF(R35<>"",R35,0) - IF(G35<>"",G35,0),9) -> 0.11922854
A36: 5Eq8C1NoLah4DaahQLMQ6wPLTSiAoiP35kVs9VMjaEqcSmdF | B36: 4843021 | C36: 2025-02-02T23:59:48+00:00 | D36: finney | E36: TAO | K36: 260.33092 | L36: 2.6901865 | M36: 257.64074 | N36: 0 | O36: 0 | P36: 347.5191253328133 | Q36: 1 | R36: 0.11778453 | S36: 40.93 | T36: 45690 | V36: ="S-"&IF(LEN(I36)=0,B36,I36&IF(F36="fee","-00",IF(LEN(G36)>0,"-01","-02"))) -> S-4843021 | W36: =COUNTIF(I:I,I36) -> 0 | X36: =IF(LEN(I36)>0,I36&IF(F36="fee","fee",IF(VALUE(G36)>0,"debit",IF(VALUE(H36)>0,"credit","error"))),"") | Y36: =ROUND(IF(ROW(U36) = 2,K36,0)+IF(H36<>"",H36,0) + IF(R36<>"",R36,0) - IF(G36<>"",G36,0),9) -> 0.11778453
A37: 5Eq8C1NoLah4DaahQLMQ6wPLTSiAoiP35kVs9VMjaEqcSmdF | B37: 4850221 | C37: 2025-02-03T23:59:48+00:00 | D37: finney | E37: TAO | K37: 260.45122 | L37: 2.6901865 | M37: 257.76103 | N37: 0 | O37: 0 | P37: 391.4238925935672 | Q37: 1 | R37: 0.12029826 | S37: 47.08 | T37: 45691 | V37: ="S-"&IF(LEN(I37)=0,B37,I37&IF(F37="fee","-00",IF(LEN(G37)>0,"-01","-02"))) -> S-4850221 | W37: =COUNTIF(I:I,I37) -> 0 | X37: =IF(LEN(I37)>0,I37&IF(F37="fee","fee",IF(VALUE(G37)>0,"debit",IF(VALUE(H37)>0,"credit","error"))),"") | Y37: =ROUND(IF(ROW(U37) = 2,K37,0)+IF(H37<>"",H37,0) + IF(R37<>"",R37,0) - IF(G37<>"",G37,0),9) -> 0.12029826
A38: 5Eq8C1NoLah4DaahQLMQ6wPLTSiAoiP35kVs9VMjaEqcSmdF | B38: 4857421 | C38: 2025-02-04T23:59:48+00:00 | D38: finney | E38: TAO | K38: 260.56887 | L38: 2.6901865 | M38: 257.87868 | N38: 0 | O38: 0 | P38: 357.5705242975157 | Q38: 1 | R38: 0.11764868 | S38: 42.06 | T38: 45692 | V38: ="S-"&IF(LEN(I38)=0,B38,I38&IF(F38="fee","-00",IF(LEN(G38)>0,"-01","-02"))) -> S-4857421 | W38: =COUNTIF(I:I,I38) -> 0 | X38: =IF(LEN(I38)>0,I38&IF(F38="fee","fee",IF(VALUE(G38)>0,"debit",IF(VALUE(H38)>0,"credit","error"))),"") | Y38: =ROUND(IF(ROW(U38) = 2,K38,0)+IF(H38<>"",H38,0) + IF(R38<>"",R38,0) - IF(G38<>"",G38,0),9) -> 0.11764868
A39: 5Eq8C1NoLah4DaahQLMQ6wPLTSiAoiP35kVs9VMjaEqcSmdF | B39: 4864621 | C39: 2025-02-05T23:59:48+00:00 | D39: finney | E39: TAO | K39: 260.68489 | L39: 2.6901865 | M39: 257.9947 | N39: 0 | O39: 0 | P39: 351.1294191389967 | Q39: 1 | R39: 0.11601707 | S39: 40.73 | T39: 45693 | V39: ="S-"&IF(LEN(I39)=0,B39,I39&IF(F39="fee","-00",IF(LEN(G39)>0,"-01","-02"))) -> S-4864621 | W39: =COUNTIF(I:I,I39) -> 0 | X39: =IF(LEN(I39)>0,I39&IF(F39="fee","fee",IF(VALUE(G39)>0,"debit",IF(VALUE(H39)>0,"credit","error"))),"") | Y39: =ROUND(IF(ROW(U39) = 2,K39,0)+IF(H39<>"",H39,0) + IF(R39<>"",R39,0) - IF(G39<>"",G39,0),9) -> 0.11601707
A40: 5Eq8C1NoLah4DaahQLMQ6wPLTSiAoiP35kVs9VMjaEqcSmdF | B40: 4871820 | C40: 2025-02-06T23:59:48+00:00 | D40: finney | E40: TAO | K40: 260.80759 | L40: 2.6901865 | M40: 258.11741 | N40: 0 | O40: 0 | P40: 325.04556 | Q40: 1 | R40: 0.12270668 | S40: 39.88 | T40: 45694 | V40: ="S-"&IF(LEN(I40)=0,B40,I40&IF(F40="fee","-00",IF(LEN(G40)>0,"-01","-02"))) -> S-4871820 | W40: =COUNTIF(I:I,I40) -> 0 | X40: =IF(LEN(I40)>0,I40&IF(F40="fee","fee",IF(VALUE(G40)>0,"debit",IF(VALUE(H40)>0,"credit","error"))),"") | Y40: =ROUND(IF(ROW(U40) = 2,K40,0)+IF(H40<>"",H40,0) + IF(R40<>"",R40,0) - IF(G40<>"",G40,0),9) -> 0.12270668
A41: 5Eq8C1NoLah4DaahQLMQ6wPLTSiAoiP35kVs9VMjaEqcSmdF | B41: 4878757 | C41: 2025-02-07T23:59:48+00:00 | D41: finney | E41: TAO | K41: 260.93076 | L41: 2.6901865 | M41: 258.24058 | N41: 0 | O41: 0 | P41: 319.8709765876021 | Q41: 1 | R41: 0.12317118 | S41: 39.39 | T41: 45695 | V41: ="S-"&IF(LEN(I41)=0,B41,I41&IF(F41="fee","-00",IF(LEN(G41)>0,"-01","-02"))) -> S-4878757 | W41: =COUNTIF(I:I,I41) -> 0 | X41: =IF(LEN(I41)>0,I41&IF(F41="fee","fee",IF(VALUE(G41)>0,"debit",IF(VALUE(H41)>0,"credit","error"))),"") | Y41: =ROUND(IF(ROW(U41) = 2,K41,0)+IF(H41<>"",H41,0) + IF(R41<>"",R41,0) - IF(G41<>"",G41,0),9) -> 0.12317118
A42: 5Eq8C1NoLah4DaahQLMQ6wPLTSiAoiP35kVs9VMjaEqcSmdF | B42: 4885596 | C42: 2025-02-08T23:59:48+00:00 | D42: finney | E42: TAO | K42: 261.05678 | L42: 2.6901865 | M42: 258.36659 | N42: 0 | O42: 0 | P42: 351.7078577448325 | Q42: 1 | R42: 0.12601254 | S42: 44.31 | T42: 45696 | V42: ="S-"&IF(LEN(I42)=0,B42,I42&IF(F42="fee","-00",IF(LEN(G42)>0,"-01","-02"))) -> S-4885596 | W42: =COUNTIF(I:I,I42) -> 0 | X42: =IF(LEN(I42)>0,I42&IF(F42="fee","fee",IF(VALUE(G42)>0,"debit",IF(VALUE(H42)>0,"credit","error"))),"") | Y42: =ROUND(IF(ROW(U42) = 2,K42,0)+IF(H42<>"",H42,0) + IF(R42<>"",R42,0) - IF(G42<>"",G42,0),9) -> 0.12601254
...

Sheet website_csv (pro)
D1: debit | F1: credit | H1: fee | N1: fee | O1: debit | P1: credit | X1: From Here Checks to make sure that the Amounts from taostats are not duplicated | AI1: -1e-10
A2: Date (UTC) | B2: Platform (Optional) | C2: Asset Sent | D2: Amount Sent | E2: Asset Received | F2: Amount Received | G2: Fee Currency (Optional) | H2: Fee Amount (Optional) | I2: Type | J2: Description (Optional) | K2: TxHash (Optional) | L2: Net Worth Amount | M2: Net Worth Currency | N2: tx hash fee count | O2: tx Hash debit count | P2: tx Hash credit count | Q2: Merge | R2: count of extrinsics | S2: Text Row or blank row | T2: Import Row | U2: Check Row | W2: fee | X2: debit | Y2: credit | Z2: fee | AB2: import checks - balances not changed | AI2: =-AI1 -> 1e-10
A3: =MID(Taostats_CSV!C3,6,2)&"/"&MID(Taostats_CSV!C3,9,2)&"/"&LEFT(Taostats_CSV!C3,4)&" "&MID(Taostats_CSV!C3,12,8) -> 12/31/2024 23:59:48 | C3: =IF(Q3,OFFSET(Taostats_CSV!$E$1,MATCH(K3&D$1,Taostats_CSV!$X:$X,0)-1,0),IF(Taostats_CSV!F3="fee",IF(VALUE(Taostats_CSV!G3)>0,Taostats_CSV!E3,""),"")) | D3: =IF(Q3,OFFSET(Taostats_CSV!$G$1,MATCH(K3&D$1,Taostats_CSV!$X:$X,0)-1,0),IF(Taostats_CSV!F3="fee",IF(VALUE(Taostats_CSV!G3)>0,Taostats_CSV!G3,""),"")) | E3: =IF(AND(Q3,P3>0),OFFSET(Taostats_CSV!$E$1,MATCH(K3&F$1,Taostats_CSV!$X:$X,0)-1,0),IF(LEN(F3)>0,Taostats_CSV!E3,"")) -> TAO | F3: =TRIM(IF(AND(Q3,P3>0),OFFSET(Taostats_CSV!$H$1,MATCH(K3&F$1,Taostats_CSV!$X:$X,0)-1,0),IF(LEN(Taostats_CSV!H3)>0,Taostats_CSV!H3,Taostats_CSV!R3))) -> 256.530086193 | G3: =IF(AND(Q3,N3=1),OFFSET(Taostats_CSV!$E$1,MATCH(K3&H$1,Taostats_CSV!$X:$X,0)-1,0),"") | H3: =IF(AND(Q3,N3=1),OFFSET(Taostats_CSV!$G$1,MATCH(K3&H$1,Taostats_CSV!$X:$X,0)-1,0),"") | I3: =IF(AND(LEN(K3)=0,LEN(F3)>0),"Income",IF(AND(O3>0,P3>0,C3<>E3),"Trade",IF(AND(NOT(Q3),Taostats_CSV!F3="fee"),'READ ME'!$C$5,""))) -> Income | J3: =SUBSTITUTE(IF(LEN(I3)=0,Taostats_CSV!F3&" "&Taostats_CSV!J3,IF(I3="Cost","Extrinsic fee","")),"_"," ") | K3: =TRIM(IF(LEN(Taostats_CSV!I3)>0,Taostats_CSV!I3,"")) | L3: =IF(Taostats_CSV!E3<>"TAO",IF(LEN(F3)>0,F3,IF(LEN(D3)>0,D3,0))*Taostats_CSV!P3,"") | M3: =IF(LEN(L3)>0,"USD","") | N3: =COUNTIF(Taostats_CSV!$X:$X,Taostats_CSV!$I3&N$1) -> 0 | O3: =COUNTIF(Taostats_CSV!$X:$X,Taostats_CSV!$I3&O$1) -> 0 | P3: =COUNTIF(Taostats_CSV!$X:$X,Taostats_CSV!$I3&P$1) -> 0 | Q3: =AND(O3<=1,N3<=1,P3<=1,O3+N3+P3>=2) -> FALSE | R3: =IF(LEN(K3)>0,COUNTIF($K$3:K3,K3),FALSE) -> FALSE | S3: =IF(Taostats_CSV!A3=Taostats_CSV!$A$2,TRUE,Taostats_CSV!G3+Taostats_CSV!H3+Taostats_CSV!R3=0) -> FALSE | T3: =AND(NOT(S3),OR(NOT(Q3),R3=1)) -> TRUE | U3: {=AND(T3,OR(O3-N3>1,P3>1,ISERROR(A3:P3)))} -> FALSE | W3: =MATCH(K3&$W$2,Taostats_CSV!$X$3:$X$1167,0) -> #N/A | X3: =VALUE(D3) -> #VALUE! | Y3: =VALUE(F3) -> 256.53009 | Z3: =VALUE(H3) -> #VALUE! | AB3: CSV | AE3: Import CSV | AH3: Check | AI3: error highlight
A4: =MID(Taostats_CSV!C4,6,2)&"/"&MID(Taostats_CSV!C4,9,2)&"/"&LEFT(Taostats_CSV!C4,4)&" "&MID(Taostats_CSV!C4,12,8) -> 01/01/2025 23:59:48 | C4: =IF(Q4,OFFSET(Taostats_CSV!$E$1,MATCH(K4&D$1,Taostats_CSV!$X:$X,0)-1,0),IF(Taostats_CSV!F4="fee",IF(VALUE(Taostats_CSV!G4)>0,Taostats_CSV!E4,""),"")) | D4: =IF(Q4,OFFSET(Taostats_CSV!$G$1,MATCH(K4&D$1,Taostats_CSV!$X:$X,0)-1,0),IF(Taostats_CSV!F4="fee",IF(VALUE(Taostats_CSV!G4)>0,Taostats_CSV!G4,""),"")) | E4: =IF(AND(Q4,P4>0),OFFSET(Taostats_CSV!$E$1,MATCH(K4&F$1,Taostats_CSV!$X:$X,0)-1,0),IF(LEN(F4)>0,Taostats_CSV!E4,"")) -> TAO | F4: =TRIM(IF(AND(Q4,P4>0),OFFSET(Taostats_CSV!$H$1,MATCH(K4&F$1,Taostats_CSV!$X:$X,0)-1,0),IF(LEN(Taostats_CSV!H4)>0,Taostats_CSV!H4,Taostats_CSV!R4))) -> 0.130885389 | G4: =IF(AND(Q4,N4=1),OFFSET(Taostats_CSV!$E$1,MATCH(K4&H$1,Taostats_CSV!$X:$X,0)-1,0),"") | H4: =IF(AND(Q4,N4=1),OFFSET(Taostats_CSV!$G$1,MATCH(K4&H$1,Taostats_CSV!$X:$X,0)-1,0),"") | I4: =IF(AND(LEN(K4)=0,LEN(F4)>0),"Income",IF(AND(O4>0,P4>0,C4<>E4),"Trade",IF(AND(NOT(Q4),Taostats_CSV!F4="fee"),'READ ME'!$C$5,""))) -> Income | J4: =SUBSTITUTE(IF(LEN(I4)=0,Taostats_CSV!F4&" "&Taostats_CSV!J4,IF(I4="Cost","Extrinsic fee","")),"_"," ") | K4: =TRIM(IF(LEN(Taostats_CSV!I4)>0,Taostats_CSV!I4,"")) | L4: =IF(Taostats_CSV!E4<>"TAO",IF(LEN(F4)>0,F4,IF(LEN(D4)>0,D4,0))*Taostats_CSV!P4,"") | M4: =IF(LEN(L4)>0,"USD","") | N4: =COUNTIF(Taostats_CSV!$X:$X,Taostats_CSV!$I4&N$1) -> 0 | O4: =COUNTIF(Taostats_CSV!$X:$X,Taostats_CSV!$I4&O$1) -> 0 | P4: =COUNTIF(Taostats_CSV!$X:$X,Taostats_CSV!$I4&P$1) -> 0 | Q4: =AND(O4<=1,N4<=1,P4<=1,O4+N4+P4>=2) -> FALSE | R4: =IF(LEN(K4)>0,COUNTIF($K$3:K4,K4),FALSE) -> FALSE | S4: =IF(Taostats_CSV!A4=Taostats_CSV!$A$2,TRUE,Taostats_CSV!G4+Taostats_CSV!H4+Taostats_CSV!R4=0) -> FALSE | T4: =AND(NOT(S4),OR(NOT(Q4),R4=1)) -> TRUE | U4: {=AND(T4,OR(O4-N4>1,P4>1,ISERROR(A4:P4)))} -> FALSE | W4: =MATCH(K4&$W$2,Taostats_CSV!$X$3:$X$1167,0) -> #N/A | X4: =VALUE(D4) -> #VALUE! | Y4: =VALUE(F4) -> 0.13088539 | Z4: =VALUE(H4) -> #VALUE! | AA4: {=_xlfn.UNIQUE(Taostats_CSV!E2:E9994)} -> Token | AB4: debit | AC4: Credit | AD4: income | AE4: debit | AF4: credit | AG4: fees | AH4: debit | AI4: credit
A5: =MID(Taostats_CSV!C5,6,2)&"/"&MID(Taostats_CSV!C5,9,2)&"/"&LEFT(Taostats_CSV!C5,4)&" "&MID(Taostats_CSV!C5,12,8) -> 01/02/2025 23:59:48 | C5: =IF(Q5,OFFSET(Taostats_CSV!$E$1,MATCH(K5&D$1,Taostats_CSV!$X:$X,0)-1,0),IF(Taostats_CSV!F5="fee",IF(VALUE(Taostats_CSV!G5)>0,Taostats_CSV!E5,""),"")) | D5: =IF(Q5,OFFSET(Taostats_CSV!$G$1,MATCH(K5&D$1,Taostats_CSV!$X:$X,0)-1,0),IF(Taostats_CSV!F5="fee",IF(VALUE(Taostats_CSV!G5)>0,Taostats_CSV!G5,""),"")) | E5: =IF(AND(Q5,P5>0),OFFSET(Taostats_CSV!$E$1,MATCH(K5&F$1,Taostats_CSV!$X:$X,0)-1,0),IF(LEN(F5)>0,Taostats_CSV!E5,"")) -> TAO | F5: =TRIM(IF(AND(Q5,P5>0),OFFSET(Taostats_CSV!$H$1,MATCH(K5&F$1,Taostats_CSV!$X:$X,0)-1,0),IF(LEN(Taostats_CSV!H5)>0,Taostats_CSV!H5,Taostats_CSV!R5))) -> 0.111661269 | G5: =IF(AND(Q5,N5=1),OFFSET(Taostats_CSV!$E$1,MATCH(K5&H$1,Taostats_CSV!$X:$X,0)-1,0),"") | H5: =IF(AND(Q5,N5=1),OFFSET(Taostats_CSV!$G$1,MATCH(K5&H$1,Taostats_CSV!$X:$X,0)-1,0),"") | I5: =IF(AND(LEN(K5)=0,LEN(F5)>0),"Income",IF(AND(O5>0,P5>0,C5<>E5),"Trade",IF(AND(NOT(Q5),Taostats_CSV!F5="fee"),'READ ME'!$C$5,""))) -> Income | J5: =SUBSTITUTE(IF(LEN(I5)=0,Taostats_CSV!F5&" "&Taostats_CSV!J5,IF(I5="Cost","Extrinsic fee","")),"_"," ") | K5: =TRIM(IF(LEN(Taostats_CSV!I5)>0,Taostats_CSV!I5,"")) | L5: =IF(Taostats_CSV!E5<>"TAO",IF(LEN(F5)>0,F5,IF(LEN(D5)>0,D5,0))*Taostats_CSV!P5,"") | M5: =IF(LEN(L5)>0,"USD","") | N5: =COUNTIF(Taostats_CSV!$X:$X,Taostats_CSV!$I5&N$1) -> 0 | O5: =COUNTIF(Taostats_CSV!$X:$X,Taostats_CSV!$I5&O$1) -> 0 | P5: =COUNTIF(Taostats_CSV!$X:$X,Taostats_CSV!$I5&P$1) -> 0 | Q5: =AND(O5<=1,N5<=1,P5<=1,O5+N5+P5>=2) -> FALSE | R5: =IF(LEN(K5)>0,COUNTIF($K$3:K5,K5),FALSE) -> FALSE | S5: =IF(Taostats_CSV!A5=Taostats_CSV!$A$2,TRUE,Taostats_CSV!G5+Taostats_CSV!H5+Taostats_CSV!R5=0) -> FALSE | T5: =AND(NOT(S5),OR(NOT(Q5),R5=1)) -> TRUE | U5: {=AND(T5,OR(O5-N5>1,P5>1,ISERROR(A5:P5)))} -> FALSE | W5: =MATCH(K5&$W$2,Taostats_CSV!$X$3:$X$1167,0) -> #N/A | X5: =VALUE(D5) -> #VALUE! | Y5: =VALUE(F5) -> 0.11166127 | Z5: =VALUE(H5) -> #VALUE! | AA5: TAO | AB5: =SUMIF(Taostats_CSV!$E:$E,AA5,Taostats_CSV!G:G) -> 454.28461 | AC5: =SUMIF(Taostats_CSV!$E:$E,AA5,Taostats_CSV!H:H) -> 186.91962 | AD5: =SUMIF(Taostats_CSV!$E:$E,AA5,Taostats_CSV!R:R) -> 267.39839 | AE5: =SUMIFS($X:$X,$C:$C,$AA5,$T:$T,TRUE) -> 454.28299 | AF5: =SUMIFS($Y:$Y,$E:$E,$AA5,$T:$T,TRUE) -> 454.31801 | AG5: =SUMIFS($H:$H,$G:$G,$AA5,$T:$T,TRUE) -> 0.001619382 | AH5: =AE5+AG5-AB5 -> 0 | AI5: =AF5-AD5-AC5 -> 0
A6: =MID(Taostats_CSV!C6,6,2)&"/"&MID(Taostats_CSV!C6,9,2)&"/"&LEFT(Taostats_CSV!C6,4)&" "&MID(Taostats_CSV!C6,12,8) -> 01/03/2025 23:59:48 | C6: =IF(Q6,OFFSET(Taostats_CSV!$E$1,MATCH(K6&D$1,Taostats_CSV!$X:$X,0)-1,0),IF(Taostats_CSV!F6="fee",IF(VALUE(Taostats_CSV!G6)>0,Taostats_CSV!E6,""),"")) | D6: =IF(Q6,OFFSET(Taostats_CSV!$G$1,MATCH(K6&D$1,Taostats_CSV!$X:$X,0)-1,0),IF(Taostats_CSV!F6="fee",IF(VALUE(Taostats_CSV!G6)>0,Taostats_CSV!G6,""),"")) | E6: =IF(AND(Q6,P6>0),OFFSET(Taostats_CSV!$E$1,MATCH(K6&F$1,Taostats_CSV!$X:$X,0)-1,0),IF(LEN(F6)>0,Taostats_CSV!E6,"")) -> TAO | F6: =TRIM(IF(AND(Q6,P6>0),OFFSET(Taostats_CSV!$H$1,MATCH(K6&F$1,Taostats_CSV!$X:$X,0)-1,0),IF(LEN(Taostats_CSV!H6)>0,Taostats_CSV!H6,Taostats_CSV!R6))) -> 0.112610101 | G6: =IF(AND(Q6,N6=1),OFFSET(Taostats_CSV!$E$1,MATCH(K6&H$1,Taostats_CSV!$X:$X,0)-1,0),"") | H6: =IF(AND(Q6,N6=1),OFFSET(Taostats_CSV!$G$1,MATCH(K6&H$1,Taostats_CSV!$X:$X,0)-1,0),"") | I6: =IF(AND(LEN(K6)=0,LEN(F6)>0),"Income",IF(AND(O6>0,P6>0,C6<>E6),"Trade",IF(AND(NOT(Q6),Taostats_CSV!F6="fee"),'READ ME'!$C$5,""))) -> Income | J6: =SUBSTITUTE(IF(LEN(I6)=0,Taostats_CSV!F6&" "&Taostats_CSV!J6,IF(I6="Cost","Extrinsic fee","")),"_"," ") | K6: =TRIM(IF(LEN(Taostats_CSV!I6)>0,Taostats_CSV!I6,"")) | L6: =IF(Taostats_CSV!E6<>"TAO",IF(LEN(F6)>0,F6,IF(LEN(D6)>0,D6,0))*Taostats_CSV!P6,"") | M6: =IF(LEN(L6)>0,"USD","") | N6: =COUNTIF(Taostats_CSV!$X:$X,Taostats_CSV!$I6&N$1) -> 0 | O6: =COUNTIF(Taostats_CSV!$X:$X,Taostats_CSV!$I6&O$1) -> 0 | P6: =COUNTIF(Taostats_CSV!$X:$X,Taostats_CSV!$I6&P$1) -> 0 | Q6: =AND(O6<=1,N6<=1,P6<=1,O6+N6+P6>=2) -> FALSE | R6: =IF(LEN(K6)>0,COUNTIF($K$3:K6,K6),FALSE) -> FALSE | S6: =IF(Taostats_CSV!A6=Taostats_CSV!$A$2,TRUE,Taostats_CSV!G6+Taostats_CSV!H6+Taostats_CSV!R6=0) -> FALSE | T6: =AND(NOT(S6),OR(NOT(Q6),R6=1)) -> TRUE | U6: {=AND(T6,OR(O6-N6>1,P6>1,ISERROR(A6:P6)))} -> FALSE | W6: =MATCH(K6&$W$2,Taostats_CSV!$X$3:$X$1167,0) -> #N/A | X6: =VALUE(D6) -> #VALUE! | Y6: =VALUE(F6) -> 0.1126101 | Z6: =VALUE(H6) -> #VALUE! | AA6: SN3 | AB6: =SUMIF(Taostats_CSV!$E:$E,AA6,Taostats_CSV!G:G) -> 280.06029 | AC6: =SUMIF(Taostats_CSV!$E:$E,AA6,Taostats_CSV!H:H) -> 201.89081 | AD6: =SUMIF(Taostats_CSV!$E:$E,AA6,Taostats_CSV!R:R) -> 78.169487 | AE6: =SUMIFS($X:$X,$C:$C,$AA6,$T:$T,TRUE) -> 280.06029 | AF6: =SUMIFS($Y:$Y,$E:$E,$AA6,$T:$T,TRUE) -> 280.06029 | AG6: =SUMIFS($H:$H,$G:$G,$AA6,$T:$T,TRUE) -> 0 | AH6: =AE6+AG6-AB6 -> 0 | AI6: =AF6-AD6-AC6 -> 0
A7: =MID(Taostats_CSV!C7,6,2)&"/"&MID(Taostats_CSV!C7,9,2)&"/"&LEFT(Taostats_CSV!C7,4)&" "&MID(Taostats_CSV!C7,12,8) -> 01/04/2025 23:59:48 | C7: =IF(Q7,OFFSET(Taostats_CSV!$E$1,MATCH(K7&D$1,Taostats_CSV!$X:$X,0)-1,0),IF(Taostats_CSV!F7="fee",IF(VALUE(Taostats_CSV!G7)>0,Taostats_CSV!E7,""),"")) | D7: =IF(Q7,OFFSET(Taostats_CSV!$G$1,MATCH(K7&D$1,Taostats_CSV!$X:$X,0)-1,0),IF(Taostats_CSV!F7="fee",IF(VALUE(Taostats_CSV!G7)>0,Taostats_CSV!G7,""),"")) | E7: =IF(AND(Q7,P7>0),OFFSET(Taostats_CSV!$E$1,MATCH(K7&F$1,Taostats_CSV!$X:$X,0)-1,0),IF(LEN(F7)>0,Taostats_CSV!E7,"")) -> TAO | F7: =TRIM(IF(AND(Q7,P7>0),OFFSET(Taostats_CSV!$H$1,MATCH(K7&F$1,Taostats_CSV!$X:$X,0)-1,0),IF(LEN(Taostats_CSV!H7)>0,Taostats_CSV!H7,Taostats_CSV!R7))) -> 0.111114908 | G7: =IF(AND(Q7,N7=1),OFFSET(Taostats_CSV!$E$1,MATCH(K7&H$1,Taostats_CSV!$X:$X,0)-1,0),"") | H7: =IF(AND(Q7,N7=1),OFFSET(Taostats_CSV!$G$1,MATCH(K7&H$1,Taostats_CSV!$X:$X,0)-1,0),"") | I7: =IF(AND(LEN(K7)=0,LEN(F7)>0),"Income",IF(AND(O7>0,P7>0,C7<>E7),"Trade",IF(AND(NOT(Q7),Taostats_CSV!F7="fee"),'READ ME'!$C$5,""))) -> Income | J7: =SUBSTITUTE(IF(LEN(I7)=0,Taostats_CSV!F7&" "&Taostats_CSV!J7,IF(I7="Cost","Extrinsic fee","")),"_"," ") | K7: =TRIM(IF(LEN(Taostats_CSV!I7)>0,Taostats_CSV!I7,"")) | L7: =IF(Taostats_CSV!E7<>"TAO",IF(LEN(F7)>0,F7,IF(LEN(D7)>0,D7,0))*Taostats_CSV!P7,"") | M7: =IF(LEN(L7)>0,"USD","") | N7: =COUNTIF(Taostats_CSV!$X:$X,Taostats_CSV!$I7&N$1) -> 0 | O7: =COUNTIF(Taostats_CSV!$X:$X,Taostats_CSV!$I7&O$1) -> 0 | P7: =COUNTIF(Taostats_CSV!$X:$X,Taostats_CSV!$I7&P$1) -> 0 | Q7: =AND(O7<=1,N7<=1,P7<=1,O7+N7+P7>=2) -> FALSE | R7: =IF(LEN(K7)>0,COUNTIF($K$3:K7,K7),FALSE) -> FALSE | S7: =IF(Taostats_CSV!A7=Taostats_CSV!$A$2,TRUE,Taostats_CSV!G7+Taostats_CSV!H7+Taostats_CSV!R7=0) -> FALSE | T7: =AND(NOT(S7),OR(NOT(Q7),R7=1)) -> TRUE | U7: {=AND(T7,OR(O7-N7>1,P7>1,ISERROR(A7:P7)))} -> FALSE | W7: =MATCH(K7&$W$2,Taostats_CSV!$X$3:$X$1167,0) -> #N/A | X7: =VALUE(D7) -> #VALUE! | Y7: =VALUE(F7) -> 0.11111491 | Z7: =VALUE(H7) -> #VALUE! | AA7: SN4 | AB7: =SUMIF(Taostats_CSV!$E:$E,AA7,Taostats_CSV!G:G) -> 203.17828 | AC7: =SUMIF(Taostats_CSV!$E:$E,AA7,Taostats_CSV!H:H) -> 125.35234 | AD7: =SUMIF(Taostats_CSV!$E:$E,AA7,Taostats_CSV!R:R) -> 77.825938 | AE7: =SUMIFS($X:$X,$C:$C,$AA7,$T:$T,TRUE) -> 203.17828 | AF7: =SUMIFS($Y:$Y,$E:$E,$AA7,$T:$T,TRUE) -> 203.17828 | AG7: =SUMIFS($H:$H,$G:$G,$AA7,$T:$T,TRUE) -> 0 | AH7: =AE7+AG7-AB7 -> 0 | AI7: =AF7-AD7-AC7 -> 0
A8: =MID(Taostats_CSV!C8,6,2)&"/"&MID(Taostats_CSV!C8,9,2)&"/"&LEFT(Taostats_CSV!C8,4)&" "&MID(Taostats_CSV!C8,12,8) -> 01/05/2025 23:59:48 | C8: =IF(Q8,OFFSET(Taostats_CSV!$E$1,MATCH(K8&D$1,Taostats_CSV!$X:$X,0)-1,0),IF(Taostats_CSV!F8="fee",IF(VALUE(Taostats_CSV!G8)>0,Taostats_CSV!E8,""),"")) | D8: =IF(Q8,OFFSET(Taostats_CSV!$G$1,MATCH(K8&D$1,Taostats_CSV!$X:$X,0)-1,0),IF(Taostats_CSV!F8="fee",IF(VALUE(Taostats_CSV!G8)>0,Taostats_CSV!G8,""),"")) | E8: =IF(AND(Q8,P8>0),OFFSET(Taostats_CSV!$E$1,MATCH(K8&F$1,Taostats_CSV!$X:$X,0)-1,0),IF(LEN(F8)>0,Taostats_CSV!E8,"")) -> TAO | F8: =TRIM(IF(AND(Q8,P8>0),OFFSET(Taostats_CSV!$H$1,MATCH(K8&F$1,Taostats_CSV!$X:$X,0)-1,0),IF(LEN(Taostats_CSV!H8)>0,Taostats_CSV!H8,Taostats_CSV!R8))) -> 0.112642665 | G8: =IF(AND(Q8,N8=1),OFFSET(Taostats_CSV!$E$1,MATCH(K8&H$1,Taostats_CSV!$X:$X,0)-1,0),"") | H8: =IF(AND(Q8,N8=1),OFFSET(Taostats_CSV!$G$1,MATCH(K8&H$1,Taostats_CSV!$X:$X,0)-1,0),"") | I8: =IF(AND(LEN(K8)=0,LEN(F8)>0),"Income",IF(AND(O8>0,P8>0,C8<>E8),"Trade",IF(AND(NOT(Q8),Taostats_CSV!F8="fee"),'READ ME'!$C$5,""))) -> Income | J8: =SUBSTITUTE(IF(LEN(I8)=0,Taostats_CSV!F8&" "&Taostats_CSV!J8,IF(I8="Cost","Extrinsic fee","")),"_"," ") | K8: =TRIM(IF(LEN(Taostats_CSV!I8)>0,Taostats_CSV!I8,"")) | L8: =IF(Taostats_CSV!E8<>"TAO",IF(LEN(F8)>0,F8,IF(LEN(D8)>0,D8,0))*Taostats_CSV!P8,"") | M8: =IF(LEN(L8)>0,"USD","") | N8: =COUNTIF(Taostats_CSV!$X:$X,Taostats_CSV!$I8&N$1) -> 0 | O8: =COUNTIF(Taostats_CSV!$X:$X,Taostats_CSV!$I8&O$1) -> 0 | P8: =COUNTIF(Taostats_CSV!$X:$X,Taostats_CSV!$I8&P$1) -> 0 | Q8: =AND(O8<=1,N8<=1,P8<=1,O8+N8+P8>=2) -> FALSE | R8: =IF(LEN(K8)>0,COUNTIF($K$3:K8,K8),FALSE) -> FALSE | S8: =IF(Taostats_CSV!A8=Taostats_CSV!$A$2,TRUE,Taostats_CSV!G8+Taostats_CSV!H8+Taostats_CSV!R8=0) -> FALSE | T8: =AND(NOT(S8),OR(NOT(Q8),R8=1)) -> TRUE | U8: {=AND(T8,OR(O8-N8>1,P8>1,ISERROR(A8:P8)))} -> FALSE | W8: =MATCH(K8&$W$2,Taostats_CSV!$X$3:$X$1167,0) -> #N/A | X8: =VALUE(D8) -> #VALUE! | Y8: =VALUE(F8) -> 0.11264267 | Z8: =VALUE(H8) -> #VALUE! | AA8: SN56 | AB8: =SUMIF(Taostats_CSV!$E:$E,AA8,Taostats_CSV!G:G) -> 176.66136 | AC8: =SUMIF(Taostats_CSV!$E:$E,AA8,Taostats_CSV!H:H) -> 129.76133 | AD8: =SUMIF(Taostats_CSV!$E:$E,AA8,Taostats_CSV!R:R) -> 46.900029 | AE8: =SUMIFS($X:$X,$C:$C,$AA8,$T:$T,TRUE) -> 176.66136 | AF8: =SUMIFS($Y:$Y,$E:$E,$AA8,$T:$T,TRUE) -> 176.66136 | AG8: =SUMIFS($H:$H,$G:$G,$AA8,$T:$T,TRUE) -> 0 | AH8: =AE8+AG8-AB8 -> 0 | AI8: =AF8-AD8-AC8 -> 0
A9: =MID(Taostats_CSV!C9,6,2)&"/"&MID(Taostats_CSV!C9,9,2)&"/"&LEFT(Taostats_CSV!C9,4)&" "&MID(Taostats_CSV!C9,12,8) -> 01/06/2025 23:59:48 | C9: =IF(Q9,OFFSET(Taostats_CSV!$E$1,MATCH(K9&D$1,Taostats_CSV!$X:$X,0)-1,0),IF(Taostats_CSV!F9="fee",IF(VALUE(Taostats_CSV!G9)>0,Taostats_CSV!E9,""),"")) | D9: =IF(Q9,OFFSET(Taostats_CSV!$G$1,MATCH(K9&D$1,Taostats_CSV!$X:$X,0)-1,0),IF(Taostats_CSV!F9="fee",IF(VALUE(Taostats_CSV!G9)>0,Taostats_CSV!G9,""),"")) | E9: =IF(AND(Q9,P9>0),OFFSET(Taostats_CSV!$E$1,MATCH(K9&F$1,Taostats_CSV!$X:$X,0)-1,0),IF(LEN(F9)>0,Taostats_CSV!E9,"")) -> TAO | F9: =TRIM(IF(AND(Q9,P9>0),OFFSET(Taostats_CSV!$H$1,MATCH(K9&F$1,Taostats_CSV!$X:$X,0)-1,0),IF(LEN(Taostats_CSV!H9)>0,Taostats_CSV!H9,Taostats_CSV!R9))) -> 0.116219871 | G9: =IF(AND(Q9,N9=1),OFFSET(Taostats_CSV!$E$1,MATCH(K9&H$1,Taostats_CSV!$X:$X,0)-1,0),"") | H9: =IF(AND(Q9,N9=1),OFFSET(Taostats_CSV!$G$1,MATCH(K9&H$1,Taostats_CSV!$X:$X,0)-1,0),"") | I9: =IF(AND(LEN(K9)=0,LEN(F9)>0),"Income",IF(AND(O9>0,P9>0,C9<>E9),"Trade",IF(AND(NOT(Q9),Taostats_CSV!F9="fee"),'READ ME'!$C$5,""))) -> Income | J9: =SUBSTITUTE(IF(LEN(I9)=0,Taostats_CSV!F9&" "&Taostats_CSV!J9,IF(I9="Cost","Extrinsic fee","")),"_"," ") | K9: =TRIM(IF(LEN(Taostats_CSV!I9)>0,Taostats_CSV!I9,"")) | L9: =IF(Taostats_CSV!E9<>"TAO",IF(LEN(F9)>0,F9,IF(LEN(D9)>0,D9,0))*Taostats_CSV!P9,"") | M9: =IF(LEN(L9)>0,"USD","") | N9: =COUNTIF(Taostats_CSV!$X:$X,Taostats_CSV!$I9&N$1) -> 0 | O9: =COUNTIF(Taostats_CSV!$X:$X,Taostats_CSV!$I9&O$1) -> 0 | P9: =COUNTIF(Taostats_CSV!$X:$X,Taostats_CSV!$I9&P$1) -> 0 | Q9: =AND(O9<=1,N9<=1,P9<=1,O9+N9+P9>=2) -> FALSE | R9: =IF(LEN(K9)>0,COUNTIF($K$3:K9,K9),FALSE) -> FALSE | S9: =IF(Taostats_CSV!A9=Taostats_CSV!$A$2,TRUE,Taostats_CSV!G9+Taostats_CSV!H9+Taostats_CSV!R9=0) -> FALSE | T9: =AND(NOT(S9),OR(NOT(Q9),R9=1)) -> TRUE | U9: {=AND(T9,OR(O9-N9>1,P9>1,ISERROR(A9:P9)))} -> FALSE | W9: =MATCH(K9&$W$2,Taostats_CSV!$X$3:$X$1167,0) -> #N/A | X9: =VALUE(D9) -> #VALUE! | Y9: =VALUE(F9) -> 0.11621987 | Z9: =VALUE(H9) -> #VALUE! | AA9: SN64 | AB9: =SUMIF(Taostats_CSV!$E:$E,AA9,Taostats_CSV!G:G) -> 92.510727 | AC9: =SUMIF(Taostats_CSV!$E:$E,AA9,Taostats_CSV!H:H) -> 66.346213 | AD9: =SUMIF(Taostats_CSV!$E:$E,AA9,Taostats_CSV!R:R) -> 26.164514 | AE9: =SUMIFS($X:$X,$C:$C,$AA9,$T:$T,TRUE) -> 92.510727 | AF9: =SUMIFS($Y:$Y,$E:$E,$AA9,$T:$T,TRUE) -> 92.510727 | AG9: =SUMIFS($H:$H,$G:$G,$AA9,$T:$T,TRUE) -> 0 | AH9: =AE9+AG9-AB9 -> 0 | AI9: =AF9-AD9-AC9 -> 0
A10: =MID(Taostats_CSV!C10,6,2)&"/"&MID(Taostats_CSV!C10,9,2)&"/"&LEFT(Taostats_CSV!C10,4)&" "&MID(Taostats_CSV!C10,12,8) -> 01/07/2025 23:59:48 | C10: =IF(Q10,OFFSET(Taostats_CSV!$E$1,MATCH(K10&D$1,Taostats_CSV!$X:$X,0)-1,0),IF(Taostats_CSV!F10="fee",IF(VALUE(Taostats_CSV!G10)>0,Taostats_CSV!E10,""),"")) | D10: =IF(Q10,OFFSET(Taostats_CSV!$G$1,MATCH(K10&D$1,Taostats_CSV!$X:$X,0)-1,0),IF(Taostats_CSV!F10="fee",IF(VALUE(Taostats_CSV!G10)>0,Taostats_CSV!G10,""),"")) | E10: =IF(AND(Q10,P10>0),OFFSET(Taostats_CSV!$E$1,MATCH(K10&F$1,Taostats_CSV!$X:$X,0)-1,0),IF(LEN(F10)>0,Taostats_CSV!E10,"")) -> TAO | F10: =TRIM(IF(AND(Q10,P10>0),OFFSET(Taostats_CSV!$H$1,MATCH(K10&F$1,Taostats_CSV!$X:$X,0)-1,0),IF(LEN(Taostats_CSV!H10)>0,Taostats_CSV!H10,Taostats_CSV!R10))) -> 0.117338691 | G10: =IF(AND(Q10,N10=1),OFFSET(Taostats_CSV!$E$1,MATCH(K10&H$1,Taostats_CSV!$X:$X,0)-1,0),"") | H10: =IF(AND(Q10,N10=1),OFFSET(Taostats_CSV!$G$1,MATCH(K10&H$1,Taostats_CSV!$X:$X,0)-1,0),"") | I10: =IF(AND(LEN(K10)=0,LEN(F10)>0),"Income",IF(AND(O10>0,P10>0,C10<>E10),"Trade",IF(AND(NOT(Q10),Taostats_CSV!F10="fee"),'READ ME'!$C$5,""))) -> Income | J10: =SUBSTITUTE(IF(LEN(I10)=0,Taostats_CSV!F10&" "&Taostats_CSV!J10,IF(I10="Cost","Extrinsic fee","")),"_"," ") | K10: =TRIM(IF(LEN(Taostats_CSV!I10)>0,Taostats_CSV!I10,"")) | L10: =IF(Taostats_CSV!E10<>"TAO",IF(LEN(F10)>0,F10,IF(LEN(D10)>0,D10,0))*Taostats_CSV!P10,"") | M10: =IF(LEN(L10)>0,"USD","") | N10: =COUNTIF(Taostats_CSV!$X:$X,Taostats_CSV!$I10&N$1) -> 0 | O10: =COUNTIF(Taostats_CSV!$X:$X,Taostats_CSV!$I10&O$1) -> 0 | P10: =COUNTIF(Taostats_CSV!$X:$X,Taostats_CSV!$I10&P$1) -> 0 | Q10: =AND(O10<=1,N10<=1,P10<=1,O10+N10+P10>=2) -> FALSE | R10: =IF(LEN(K10)>0,COUNTIF($K$3:K10,K10),FALSE) -> FALSE | S10: =IF(Taostats_CSV!A10=Taostats_CSV!$A$2,TRUE,Taostats_CSV!G10+Taostats_CSV!H10+Taostats_CSV!R10=0) -> FALSE | T10: =AND(NOT(S10),OR(NOT(Q10),R10=1)) -> TRUE | U10: {=AND(T10,OR(O10-N10>1,P10>1,ISERROR(A10:P10)))} -> FALSE | W10: =MATCH(K10&$W$2,Taostats_CSV!$X$3:$X$1167,0) -> #N/A | X10: =VALUE(D10) -> #VALUE! | Y10: =VALUE(F10) -> 0.11733869 | Z10: =VALUE(H10) -> #VALUE! | AA10: 0 | AB10: =SUMIF(Taostats_CSV!$E:$E,AA10,Taostats_CSV!G:G) -> 0 | AC10: =SUMIF(Taostats_CSV!$E:$E,AA10,Taostats_CSV!H:H) -> 0 | AD10: =SUMIF(Taostats_CSV!$E:$E,AA10,Taostats_CSV!R:R) -> 0 | AE10: =SUMIFS($X:$X,$C:$C,$AA10,$T:$T,TRUE) -> 0 | AF10: =SUMIFS($Y:$Y,$E:$E,$AA10,$T:$T,TRUE) -> 0 | AG10: =SUMIFS($H:$H,$G:$G,$AA10,$T:$T,TRUE) -> 0 | AH10: =AE10+AG10-AB10 -> 0 | AI10: =AF10-AD10-AC10 -> 0
A11: =MID(Taostats_CSV!C11,6,2)&"/"&MID(Taostats_CSV!C11,9,2)&"/"&LEFT(Taostats_CSV!C11,4)&" "&MID(Taostats_CSV!C11,12,8) -> 01/08/2025 23:59:48 | C11: =IF(Q11,OFFSET(Taostats_CSV!$E$1,MATCH(K11&D$1,Taostats_CSV!$X:$X,0)-1,0),IF(Taostats_CSV!F11="fee",IF(VALUE(Taostats_CSV!G11)>0,Taostats_CSV!E11,""),"")) | D11: =IF(Q11,OFFSET(Taostats_CSV!$G$1,MATCH(K11&D$1,Taostats_CSV!$X:$X,0)-1,0),IF(Taostats_CSV!F11="fee",IF(VALUE(Taostats_CSV!G11)>0,Taostats_CSV!G11,""),"")) | E11: =IF(AND(Q11,P11>0),OFFSET(Taostats_CSV!$E$1,MATCH(K11&F$1,Taostats_CSV!$X:$X,0)-1,0),IF(LEN(F11)>0,Taostats_CSV!E11,"")) -> TAO | F11: =TRIM(IF(AND(Q11,P11>0),OFFSET(Taostats_CSV!$H$1,MATCH(K11&F$1,Taostats_CSV!$X:$X,0)-1,0),IF(LEN(Taostats_CSV!H11)>0,Taostats_CSV!H11,Taostats_CSV!R11))) -> 0.11603302 | G11: =IF(AND(Q11,N11=1),OFFSET(Taostats_CSV!$E$1,MATCH(K11&H$1,Taostats_CSV!$X:$X,0)-1,0),"") | H11: =IF(AND(Q11,N11=1),OFFSET(Taostats_CSV!$G$1,MATCH(K11&H$1,Taostats_CSV!$X:$X,0)-1,0),"") | I11: =IF(AND(LEN(K11)=0,LEN(F11)>0),"Income",IF(AND(O11>0,P11>0,C11<>E11),"Trade",IF(AND(NOT(Q11),Taostats_CSV!F11="fee"),'READ ME'!$C$5,""))) -> Income | J11: =SUBSTITUTE(IF(LEN(I11)=0,Taostats_CSV!F11&" "&Taostats_CSV!J11,IF(I11="Cost","Extrinsic fee","")),"_"," ") | K11: =TRIM(IF(LEN(Taostats_CSV!I11)>0,Taostats_CSV!I11,"")) | L11: =IF(Taostats_CSV!E11<>"TAO",IF(LEN(F11)>0,F11,IF(LEN(D11)>0,D11,0))*Taostats_CSV!P11,"") | M11: =IF(LEN(L11)>0,"USD","") | N11: =COUNTIF(Taostats_CSV!$X:$X,Taostats_CSV!$I11&N$1) -> 0 | O11: =COUNTIF(Taostats_CSV!$X:$X,Taostats_CSV!$I11&O$1) -> 0 | P11: =COUNTIF(Taostats_CSV!$X:$X,Taostats_CSV!$I11&P$1) -> 0 | Q11: =AND(O11<=1,N11<=1,P11<=1,O11+N11+P11>=2) -> FALSE | R11: =IF(LEN(K11)>0,COUNTIF($K$3:K11,K11),FALSE) -> FALSE | S11: =IF(Taostats_CSV!A11=Taostats_CSV!$A$2,TRUE,Taostats_CSV!G11+Taostats_CSV!H11+Taostats_CSV!R11=0) -> FALSE | T11: =AND(NOT(S11),OR(NOT(Q11),R11=1)) -> TRUE | U11: {=AND(T11,OR(O11-N11>1,P11>1,ISERROR(A11:P11)))} -> FALSE | W11: =MATCH(K11&$W$2,Taostats_CSV!$X$3:$X$1167,0) -> #N/A | X11: =VALUE(D11) -> #VALUE! | Y11: =VALUE(F11) -> 0.11603302 | Z11: =VALUE(H11) -> #VALUE! | AB11: =SUMIF(Taostats_CSV!$E:$E,AA11,Taostats_CSV!G:G) -> 0 | AC11: =SUMIF(Taostats_CSV!$E:$E,AA11,Taostats_CSV!H:H) -> 0 | AD11: =SUMIF(Taostats_CSV!$E:$E,AA11,Taostats_CSV!R:R) -> 0 | AE11: =SUMIFS($X:$X,$C:$C,$AA11,$T:$T,TRUE) -> 0 | AF11: =SUMIFS($Y:$Y,$E:$E,$AA11,$T:$T,TRUE) -> 0 | AG11: =SUMIFS($H:$H,$G:$G,$AA11,$T:$T,TRUE) -> 0 | AH11: =AE11+AG11-AB11 -> 0 | AI11: =AF11-AD11-AC11 -> 0
A12: =MID(Taostats_CSV!C12,6,2)&"/"&MID(Taostats_CSV!C12,9,2)&"/"&LEFT(Taostats_CSV!C12,4)&" "&MID(Taostats_CSV!C12,12,8) -> 01/09/2025 23:59:48 | C12: =IF(Q12,OFFSET(Taostats_CSV!$E$1,MATCH(K12&D$1,Taostats_CSV!$X:$X,0)-1,0),IF(Taostats_CSV!F12="fee",IF(VALUE(Taostats_CSV!G12)>0,Taostats_CSV!E12,""),"")) | D12: =IF(Q12,OFFSET(Taostats_CSV!$G$1,MATCH(K12&D$1,Taostats_CSV!$X:$X,0)-1,0),IF(Taostats_CSV!F12="fee",IF(VALUE(Taostats_CSV!G12)>0,Taostats_CSV!G12,""),"")) | E12: =IF(AND(Q12,P12>0),OFFSET(Taostats_CSV!$E$1,MATCH(K12&F$1,Taostats_CSV!$X:$X,0)-1,0),IF(LEN(F12)>0,Taostats_CSV!E12,"")) -> TAO | F12: =TRIM(IF(AND(Q12,P12>0),OFFSET(Taostats_CSV!$H$1,MATCH(K12&F$1,Taostats_CSV!$X:$X,0)-1,0),IF(LEN(Taostats_CSV!H12)>0,Taostats_CSV!H12,Taostats_CSV!R12))) -> 0.110048595 | G12: =IF(AND(Q12,N12=1),OFFSET(Taostats_CSV!$E$1,MATCH(K12&H$1,Taostats_CSV!$X:$X,0)-1,0),"") | H12: =IF(AND(Q12,N12=1),OFFSET(Taostats_CSV!$G$1,MATCH(K12&H$1,Taostats_CSV!$X:$X,0)-1,0),"") | I12: =IF(AND(LEN(K12)=0,LEN(F12)>0),"Income",IF(AND(O12>0,P12>0,C12<>E12),"Trade",IF(AND(NOT(Q12),Taostats_CSV!F12="fee"),'READ ME'!$C$5,""))) -> Income | J12: =SUBSTITUTE(IF(LEN(I12)=0,Taostats_CSV!F12&" "&Taostats_CSV!J12,IF(I12="Cost","Extrinsic fee","")),"_"," ") | K12: =TRIM(IF(LEN(Taostats_CSV!I12)>0,Taostats_CSV!I12,"")) | L12: =IF(Taostats_CSV!E12<>"TAO",IF(LEN(F12)>0,F12,IF(LEN(D12)>0,D12,0))*Taostats_CSV!P12,"") | M12: =IF(LEN(L12)>0,"USD","") | N12: =COUNTIF(Taostats_CSV!$X:$X,Taostats_CSV!$I12&N$1) -> 0 | O12: =COUNTIF(Taostats_CSV!$X:$X,Taostats_CSV!$I12&O$1) -> 0 | P12: =COUNTIF(Taostats_CSV!$X:$X,Taostats_CSV!$I12&P$1) -> 0 | Q12: =AND(O12<=1,N12<=1,P12<=1,O12+N12+P12>=2) -> FALSE | R12: =IF(LEN(K12)>0,COUNTIF($K$3:K12,K12),FALSE) -> FALSE | S12: =IF(Taostats_CSV!A12=Taostats_CSV!$A$2,TRUE,Taostats_CSV!G12+Taostats_CSV!H12+Taostats_CSV!R12=0) -> FALSE | T12: =AND(NOT(S12),OR(NOT(Q12),R12=1)) -> TRUE | U12: {=AND(T12,OR(O12-N12>1,P12>1,ISERROR(A12:P12)))} -> FALSE | W12: =MATCH(K12&$W$2,Taostats_CSV!$X$3:$X$1167,0) -> #N/A | X12: =VALUE(D12) -> #VALUE! | Y12: =VALUE(F12) -> 0.11004859 | Z12: =VALUE(H12) -> #VALUE! | AB12: =SUMIF(Taostats_CSV!$E:$E,AA12,Taostats_CSV!G:G) -> 0 | AC12: =SUMIF(Taostats_CSV!$E:$E,AA12,Taostats_CSV!H:H) -> 0 | AD12: =SUMIF(Taostats_CSV!$E:$E,AA12,Taostats_CSV!R:R) -> 0 | AE12: =SUMIFS($X:$X,$C:$C,$AA12,$T:$T,TRUE) -> 0 | AF12: =SUMIFS($Y:$Y,$E:$E,$AA12,$T:$T,TRUE) -> 0 | AG12: =SUMIFS($H:$H,$G:$G,$AA12,$T:$T,TRUE) -> 0 | AH12: =AE12+AG12-AB12 -> 0 | AI12: =AF12-AD12-AC12 -> 0
A13: =MID(Taostats_CSV!C13,6,2)&"/"&MID(Taostats_CSV!C13,9,2)&"/"&LEFT(Taostats_CSV!C13,4)&" "&MID(Taostats_CSV!C13,12,8) -> 01/10/2025 23:59:48 | C13: =IF(Q13,OFFSET(Taostats_CSV!$E$1,MATCH(K13&D$1,Taostats_CSV!$X:$X,0)-1,0),IF(Taostats_CSV!F13="fee",IF(VALUE(Taostats_CSV!G13)>0,Taostats_CSV!E13,""),"")) | D13: =IF(Q13,OFFSET(Taostats_CSV!$G$1,MATCH(K13&D$1,Taostats_CSV!$X:$X,0)-1,0),IF(Taostats_CSV!F13="fee",IF(VALUE(Taostats_CSV!G13)>0,Taostats_CSV!G13,""),"")) | E13: =IF(AND(Q13,P13>0),OFFSET(Taostats_CSV!$E$1,MATCH(K13&F$1,Taostats_CSV!$X:$X,0)-1,0),IF(LEN(F13)>0,Taostats_CSV!E13,"")) -> TAO | F13: =TRIM(IF(AND(Q13,P13>0),OFFSET(Taostats_CSV!$H$1,MATCH(K13&F$1,Taostats_CSV!$X:$X,0)-1,0),IF(LEN(Taostats_CSV!H13)>0,Taostats_CSV!H13,Taostats_CSV!R13))) -> 0.110197807 | G13: =IF(AND(Q13,N13=1),OFFSET(Taostats_CSV!$E$1,MATCH(K13&H$1,Taostats_CSV!$X:$X,0)-1,0),"") | H13: =IF(AND(Q13,N13=1),OFFSET(Taostats_CSV!$G$1,MATCH(K13&H$1,Taostats_CSV!$X:$X,0)-1,0),"") | I13: =IF(AND(LEN(K13)=0,LEN(F13)>0),"Income",IF(AND(O13>0,P13>0,C13<>E13),"Trade",IF(AND(NOT(Q13),Taostats_CSV!F13="fee"),'READ ME'!$C$5,""))) -> Income | J13: =SUBSTITUTE(IF(LEN(I13)=0,Taostats_CSV!F13&" "&Taostats_CSV!J13,IF(I13="Cost","Extrinsic fee","")),"_"," ") | K13: =TRIM(IF(LEN(Taostats_CSV!I13)>0,Taostats_CSV!I13,"")) | L13: =IF(Taostats_CSV!E13<>"TAO",IF(LEN(F13)>0,F13,IF(LEN(D13)>0,D13,0))*Taostats_CSV!P13,"") | M13: =IF(LEN(L13)>0,"USD","") | N13: =COUNTIF(Taostats_CSV!$X:$X,Taostats_CSV!$I13&N$1) -> 0 | O13: =COUNTIF(Taostats_CSV!$X:$X,Taostats_CSV!$I13&O$1) -> 0 | P13: =COUNTIF(Taostats_CSV!$X:$X,Taostats_CSV!$I13&P$1) -> 0 | Q13: =AND(O13<=1,N13<=1,P13<=1,O13+N13+P13>=2) -> FALSE | R13: =IF(LEN(K13)>0,COUNTIF($K$3:K13,K13),FALSE) -> FALSE | S13: =IF(Taostats_CSV!A13=Taostats_CSV!$A$2,TRUE,Taostats_CSV!G13+Taostats_CSV!H13+Taostats_CSV!R13=0) -> FALSE | T13: =AND(NOT(S13),OR(NOT(Q13),R13=1)) -> TRUE | U13: {=AND(T13,OR(O13-N13>1,P13>1,ISERROR(A13:P13)))} -> FALSE | W13: =MATCH(K13&$W$2,Taostats_CSV!$X$3:$X$1167,0) -> #N/A | X13: =VALUE(D13) -> #VALUE! | Y13: =VALUE(F13) -> 0.11019781 | Z13: =VALUE(H13) -> #VALUE! | AB13: =SUMIF(Taostats_CSV!$E:$E,AA13,Taostats_CSV!G:G) -> 0 | AC13: =SUMIF(Taostats_CSV!$E:$E,AA13,Taostats_CSV!H:H) -> 0 | AD13: =SUMIF(Taostats_CSV!$E:$E,AA13,Taostats_CSV!R:R) -> 0 | AE13: =SUMIFS($X:$X,$C:$C,$AA13,$T:$T,TRUE) -> 0 | AF13: =SUMIFS($Y:$Y,$E:$E,$AA13,$T:$T,TRUE) -> 0 | AG13: =SUMIFS($H:$H,$G:$G,$AA13,$T:$T,TRUE) -> 0 | AH13: =AE13+AG13-AB13 -> 0 | AI13: =AF13-AD13-AC13 -> 0
A14: =MID(Taostats_CSV!C14,6,2)&"/"&MID(Taostats_CSV!C14,9,2)&"/"&LEFT(Taostats_CSV!C14,4)&" "&MID(Taostats_CSV!C14,12,8) -> 01/11/2025 23:59:48 | C14: =IF(Q14,OFFSET(Taostats_CSV!$E$1,MATCH(K14&D$1,Taostats_CSV!$X:$X,0)-1,0),IF(Taostats_CSV!F14="fee",IF(VALUE(Taostats_CSV!G14)>0,Taostats_CSV!E14,""),"")) | D14: =IF(Q14,OFFSET(Taostats_CSV!$G$1,MATCH(K14&D$1,Taostats_CSV!$X:$X,0)-1,0),IF(Taostats_CSV!F14="fee",IF(VALUE(Taostats_CSV!G14)>0,Taostats_CSV!G14,""),"")) | E14: =IF(AND(Q14,P14>0),OFFSET(Taostats_CSV!$E$1,MATCH(K14&F$1,Taostats_CSV!$X:$X,0)-1,0),IF(LEN(F14)>0,Taostats_CSV!E14,"")) -> TAO | F14: =TRIM(IF(AND(Q14,P14>0),OFFSET(Taostats_CSV!$H$1,MATCH(K14&F$1,Taostats_CSV!$X:$X,0)-1,0),IF(LEN(Taostats_CSV!H14)>0,Taostats_CSV!H14,Taostats_CSV!R14))) -> 0.112062363 | G14: =IF(AND(Q14,N14=1),OFFSET(Taostats_CSV!$E$1,MATCH(K14&H$1,Taostats_CSV!$X:$X,0)-1,0),"") | H14: =IF(AND(Q14,N14=1),OFFSET(Taostats_CSV!$G$1,MATCH(K14&H$1,Taostats_CSV!$X:$X,0)-1,0),"") | I14: =IF(AND(LEN(K14)=0,LEN(F14)>0),"Income",IF(AND(O14>0,P14>0,C14<>E14),"Trade",IF(AND(NOT(Q14),Taostats_CSV!F14="fee"),'READ ME'!$C$5,""))) -> Income | J14: =SUBSTITUTE(IF(LEN(I14)=0,Taostats_CSV!F14&" "&Taostats_CSV!J14,IF(I14="Cost","Extrinsic fee","")),"_"," ") | K14: =TRIM(IF(LEN(Taostats_CSV!I14)>0,Taostats_CSV!I14,"")) | L14: =IF(Taostats_CSV!E14<>"TAO",IF(LEN(F14)>0,F14,IF(LEN(D14)>0,D14,0))*Taostats_CSV!P14,"") | M14: =IF(LEN(L14)>0,"USD","") | N14: =COUNTIF(Taostats_CSV!$X:$X,Taostats_CSV!$I14&N$1) -> 0 | O14: =COUNTIF(Taostats_CSV!$X:$X,Taostats_CSV!$I14&O$1) -> 0 | P14: =COUNTIF(Taostats_CSV!$X:$X,Taostats_CSV!$I14&P$1) -> 0 | Q14: =AND(O14<=1,N14<=1,P14<=1,O14+N14+P14>=2) -> FALSE | R14: =IF(LEN(K14)>0,COUNTIF($K$3:K14,K14),FALSE) -> FALSE | S14: =IF(Taostats_CSV!A14=Taostats_CSV!$A$2,TRUE,Taostats_CSV!G14+Taostats_CSV!H14+Taostats_CSV!R14=0) -> FALSE | T14: =AND(NOT(S14),OR(NOT(Q14),R14=1)) -> TRUE | U14: {=AND(T14,OR(O14-N14>1,P14>1,ISERROR(A14:P14)))} -> FALSE | W14: =MATCH(K14&$W$2,Taostats_CSV!$X$3:$X$1167,0) -> #N/A | X14: =VALUE(D14) -> #VALUE! | Y14: =VALUE(F14) -> 0.11206236 | Z14: =VALUE(H14) -> #VALUE! | AB14: =SUMIF(Taostats_CSV!$E:$E,AA14,Taostats_CSV!G:G) -> 0 | AC14: =SUMIF(Taostats_CSV!$E:$E,AA14,Taostats_CSV!H:H) -> 0 | AD14: =SUMIF(Taostats_CSV!$E:$E,AA14,Taostats_CSV!R:R) -> 0 | AE14: =SUMIFS($X:$X,$C:$C,$AA14,$T:$T,TRUE) -> 0 | AF14: =SUMIFS($Y:$Y,$E:$E,$AA14,$T:$T,TRUE) -> 0 | AG14: =SUMIFS($H:$H,$G:$G,$AA14,$T:$T,TRUE) -> 0 | AH14: =AE14+AG14-AB14 -> 0 | AI14: =AF14-AD14-AC14 -> 0
A15: =MID(Taostats_CSV!C15,6,2)&"/"&MID(Taostats_CSV!C15,9,2)&"/"&LEFT(Taostats_CSV!C15,4)&" "&MID(Taostats_CSV!C15,12,8) -> 01/12/2025 23:59:48 | C15: =IF(Q15,OFFSET(Taostats_CSV!$E$1,MATCH(K15&D$1,Taostats_CSV!$X:$X,0)-1,0),IF(Taostats_CSV!F15="fee",IF(VALUE(Taostats_CSV!G15)>0,Taostats_CSV!E15,""),"")) | D15: =IF(Q15,OFFSET(Taostats_CSV!$G$1,MATCH(K15&D$1,Taostats_CSV!$X:$X,0)-1,0),IF(Taostats_CSV!F15="fee",IF(VALUE(Taostats_CSV!G15)>0,Taostats_CSV!G15,""),"")) | E15: =IF(AND(Q15,P15>0),OFFSET(Taostats_CSV!$E$1,MATCH(K15&F$1,Taostats_CSV!$X:$X,0)-1,0),IF(LEN(F15)>0,Taostats_CSV!E15,"")) -> TAO | F15: =TRIM(IF(AND(Q15,P15>0),OFFSET(Taostats_CSV!$H$1,MATCH(K15&F$1,Taostats_CSV!$X:$X,0)-1,0),IF(LEN(Taostats_CSV!H15)>0,Taostats_CSV!H15,Taostats_CSV!R15))) -> 0.111740714 | G15: =IF(AND(Q15,N15=1),OFFSET(Taostats_CSV!$E$1,MATCH(K15&H$1,Taostats_CSV!$X:$X,0)-1,0),"") | H15: =IF(AND(Q15,N15=1),OFFSET(Taostats_CSV!$G$1,MATCH(K15&H$1,Taostats_CSV!$X:$X,0)-1,0),"") | I15: =IF(AND(LEN(K15)=0,LEN(F15)>0),"Income",IF(AND(O15>0,P15>0,C15<>E15),"Trade",IF(AND(NOT(Q15),Taostats_CSV!F15="fee"),'READ ME'!$C$5,""))) -> Income | J15: =SUBSTITUTE(IF(LEN(I15)=0,Taostats_CSV!F15&" "&Taostats_CSV!J15,IF(I15="Cost","Extrinsic fee","")),"_"," ") | K15: =TRIM(IF(LEN(Taostats_CSV!I15)>0,Taostats_CSV!I15,"")) | L15: =IF(Taostats_CSV!E15<>"TAO",IF(LEN(F15)>0,F15,IF(LEN(D15)>0,D15,0))*Taostats_CSV!P15,"") | M15: =IF(LEN(L15)>0,"USD","") | N15: =COUNTIF(Taostats_CSV!$X:$X,Taostats_CSV!$I15&N$1) -> 0 | O15: =COUNTIF(Taostats_CSV!$X:$X,Taostats_CSV!$I15&O$1) -> 0 | P15: =COUNTIF(Taostats_CSV!$X:$X,Taostats_CSV!$I15&P$1) -> 0 | Q15: =AND(O15<=1,N15<=1,P15<=1,O15+N15+P15>=2) -> FALSE | R15: =IF(LEN(K15)>0,COUNTIF($K$3:K15,K15),FALSE) -> FALSE | S15: =IF(Taostats_CSV!A15=Taostats_CSV!$A$2,TRUE,Taostats_CSV!G15+Taostats_CSV!H15+Taostats_CSV!R15=0) -> FALSE | T15: =AND(NOT(S15),OR(NOT(Q15),R15=1)) -> TRUE | U15: {=AND(T15,OR(O15-N15>1,P15>1,ISERROR(A15:P15)))} -> FALSE | W15: =MATCH(K15&$W$2,Taostats_CSV!$X$3:$X$1167,0) -> #N/A | X15: =VALUE(D15) -> #VALUE! | Y15: =VALUE(F15) -> 0.11174071 | Z15: =VALUE(H15) -> #VALUE! | AB15: =SUMIF(Taostats_CSV!$E:$E,AA15,Taostats_CSV!G:G) -> 0 | AC15: =SUMIF(Taostats_CSV!$E:$E,AA15,Taostats_CSV!H:H) -> 0 | AD15: =SUMIF(Taostats_CSV!$E:$E,AA15,Taostats_CSV!R:R) -> 0 | AE15: =SUMIFS($X:$X,$C:$C,$AA15,$T:$T,TRUE) -> 0 | AF15: =SUMIFS($Y:$Y,$E:$E,$AA15,$T:$T,TRUE) -> 0 | AG15: =SUMIFS($H:$H,$G:$G,$AA15,$T:$T,TRUE) -> 0 | AH15: =AE15+AG15-AB15 -> 0 | AI15: =AF15-AD15-AC15 -> 0
