Workbook

Sheet READ ME
B1: This template is designed to get you started in your import to cointracker
B2: As we do not know your circumstances or the tax advice that you have received please modify it to suit your circumstances
B3: all income is classified as other_income (could be miner or staker)
B5: Any extrinsic that has more than one credit, one debit and a "fee" must be manually changed (e.g. batch or portfolio rebalance)
A7: Instructions:
A8: 1 | B8: Copy paste the contents of every csv into the Taostats_CSV tab
A9: 2 | B9: Make sure that the additional columns after blank in the Taostats_CSV column are copied down to match the number of rows imported
C10: The Sort Order is optional - It reorders to increasing block order
C11: The Lookup Helper is not optional - it is necessary for the tab website_csv(pro) to work
A12: 3 | B12: Optional Sort Taostats_CSV using the Sort Order
A13: 4 | B13: On the website_csv(pro) - Copy the 2nd row down on the sheet for as many rows are you have in the Taostats_CSV
A14: 5 | B14: Filter the rows using Check Row (column T) for any TRUE and correct the error in the Taostats_CSV tab
C15: Note: if the Import Row is FALSE and you do not need to make a change you can ignore Check Row
A16: 6 | B16: Filter Rows using Import Row = TRUE for the rows to be imported
A17: 7 | B17: on website_csv(pro) Check the Column AG and AH for error highlight - must be zero or the maths is wrong somewhere
A18: 8 | B18: on website_csv(pro) copy the values from column titles Date through to Tag to a csv file (the other columns can be copies - they will be ignored as the column title does not match)
A20: Method to import Batches
A21: 1 | B21: Filter the Taostats_CSV sheet using Count of extrinsic >3 (most batches)
A22: 2 | B22: Search for the extrinsic on Taostats
C23: Using the StakeRemoved Event will point you towards the correct match - but be aware you might have to sum some of them
A24: 3 | B24: Manually join the two sides of the transaction together by appending to the Extrinsic-ID a letter or number e.g. 5013009-0009 -> 5013009-0009-A
A25: 4 | B25: The website_csv(pro) tab will merge the transactions together for you - see example below
A27: Notes:
A28: 1 | B28: Each Taostats_CSV includes the opening balance - this is for verification purposes with accounting software balance - this row is usually not imported
A29: 2 | B29: Again a warning - batch transactions you have to work it out yourself
A32: valid tags for cointracker
A33: source | B33: https://support.cointracker.io/hc/en-us/articles/4413049710225-Transaction-category-definitions
B35: Batch
B45: is converted to website_csv(pro)

Sheet Taostats_CSV
A2: Coldkey | B2: Block number | C2: Timestamp | D2: Network | E2: Token | F2: Transaction type | G2: Debit amount | H2: Credit amount | I2: Extrinsic ID | J2: Additional data | K2: Total balance | L2: Free balance | M2: Staked balance | N2: Locked balance | O2: Reserved balance | P2: Token price in USD | Q2: Token price in TAO | R2: Daily income | S2: Daily income USD | T2: Date | U2: blank | V2: Sort Order | W2: Count of extrinsic | X2: Lookup Helper | Y2: Net Amount (for pivot table)
A3: 5Eq8C1NoLah4DaahQLMQ6wPLTSiAoiP35kVs9VMjaEqcSmdF | B3: 4605427 | C3: 2024-12-31T23:59:48+00:00 | D3: finney | E3: TAO | K3: 256.53009 | L3: 2.6901865 | M3: 253.8399 | N3: 0 | O3: 0 | P3: 439.7119272666333 | Q3: 1 | V3: ="S-"&IF(LEN(I3)=0,B3,I3&IF(F3="fee","-00",IF(LEN(G3)>0,"-01","-02"))) -> S-4605427 | W3: =COUNTIF(I:I,I3) -> 0 | X3: =IF(LEN(I3)>0,I3&IF(F3="fee","fee",IF(VALUE(G3)>0,"debit",IF(VALUE(H3)>0,"credit","error"))),"") | Y3: =ROUND(IF(ROW(U3) = 2,K3,0)+IF(H3<>"",H3,0) + IF(R3<>"",R3,0) - IF(G3<>"",G3,0),9) -> 0

Sheet website_csv (pro)
B1: debit | D1: credit | F1: fee | M1: fee | N1: debit | O1: credit | W1: From Here Checks to make sure that the Amounts from taostats are not duplicated | AH1: -1e-10
A2: Date | B2: Sent Quantity | C2: Sent Currency | D2: Received Quantity | E2: Received Currency | F2: Fee Amount | G2: Fee Currency | H2: Net Worth Amount | I2: Net Worth Currency | J2: Tag | K2: Received Comment | L2: Transaction Hash | M2: tx hash fee count | N2: tx Hash debit count | O2: tx Hash credit count | P2: Merge | Q2: count of extrinsics | R2: Text Row or blank row | S2: Import Row | T2: Check Row | V2: fee | W2: debit | X2: credit | Y2: fee | AA2: import checks - balances not changed | AH2: =-AH1 -> 1e-10
A3: =LEFT(Taostats_CSV!C3,10)&" "&MID(Taostats_CSV!C3,12,8)&" UTC" -> 2024-12-31 23:59:48 UTC | B3: =IF(P3,OFFSET(Taostats_CSV!$G$1,MATCH(L3&B$1,Taostats_CSV!$X:$X,0)-1,0),IF(Taostats_CSV!F3="fee","0",IF(VALUE(Taostats_CSV!G3)>0,Taostats_CSV!G3,""))) | C3: =IF(P3,OFFSET(Taostats_CSV!$E$1,MATCH(L3&B$1,Taostats_CSV!$X:$X,0)-1,0),IF(Taostats_CSV!F3="fee","TAO",IF(VALUE(Taostats_CSV!G3)>0,Taostats_CSV!E3,""))) | D3: =TRIM(IF(AND(P3,O3>0),OFFSET(Taostats_CSV!$H$1,MATCH(L3&D$1,Taostats_CSV!$X:$X,0)-1,0),IF(LEN(Taostats_CSV!H3)>0,Taostats_CSV!H3,Taostats_CSV!R3))) | E3: =IF(AND(P3,O3>0),OFFSET(Taostats_CSV!$E$1,MATCH(L3&D$1,Taostats_CSV!$X:$X,0)-1,0),IF(LEN(D3)>0,Taostats_CSV!E3,"")) | F3: =IF(AND(P3,M3=1),OFFSET(Taostats_CSV!$G$1,MATCH(L3&F$1,Taostats_CSV!$X:$X,0)-1,0),IF(Taostats_CSV!F3="fee",Taostats_CSV!G3,"")) | G3: =IF(AND(P3,M3=1),OFFSET(Taostats_CSV!$E$1,MATCH(L3&F$1,Taostats_CSV!$X:$X,0)-1,0),IF(Taostats_CSV!F3="fee",Taostats_CSV!E3,"")) | H3: =IF(Taostats_CSV!E3<>"TAO",IF(LEN(D3)>0,D3,IF(LEN(B3)>0,B3,0))*Taostats_CSV!P3,"") | I3: =IF(LEN(H3)>0,"USD","") | J3: =IF(AND(LEN(L3)=0,LEN(D3)>0),"other_income",IF(AND(N3>0,O3>0,C3<>E3),"bridge","")) | K3: =SUBSTITUTE(IF(LEN(J3)=0,Taostats_CSV!F3&" "&Taostats_CSV!J3,IF(J3="Cost","Extrinsic fee","")),"_"," ") | L3: =TRIM(IF(LEN(Taostats_CSV!I3)>0,Taostats_CSV!I3,"")) | M3: =COUNTIF(Taostats_CSV!$X:$X,Taostats_CSV!$I3&M$1) -> 0 | N3: =COUNTIF(Taostats_CSV!$X:$X,Taostats_CSV!$I3&N$1) -> 0 | O3: =COUNTIF(Taostats_CSV!$X:$X,Taostats_CSV!$I3&O$1) -> 0 | P3: =AND(N3<=1,M3<=1,O3<=1,N3+M3+O3>=2) -> FALSE | Q3: =IF(LEN(L3)>0,COUNTIF($L$3:L3,L3),FALSE) -> FALSE | R3: =IF(Taostats_CSV!A3=Taostats_CSV!$A$2,TRUE,Taostats_CSV!G3+Taostats_CSV!H3+Taostats_CSV!R3=0) -> TRUE | S3: =AND(NOT(R3),OR(NOT(P3),Q3=1)) -> FALSE | T3: {=OR(N3-M3>1,O3>1,ISERROR(A3:O3))} -> FALSE | V3: =MATCH(L3&$V$2,Taostats_CSV!$X$3:$X$3,0) -> #N/A | W3: =VALUE(B3) -> #VALUE! | X3: =VALUE(D3) -> #VALUE! | Y3: =VALUE(F3) -> #VALUE! | AA3: CSV | AD3: Import CSV | AG3: Check | AH3: error highlight
Z4: {=_xlfn.UNIQUE(Taostats_CSV!E2:E8820)} -> Token | AA4: debit | AB4: Credit | AC4: income | AD4: debit | AE4: credit | AF4: fees | AG4: debit | AH4: credit
Z5: TAO | AA5: =SUMIF(Taostats_CSV!$E:$E,Z5,Taostats_CSV!G:G) -> 0 | AB5: =SUMIF(Taostats_CSV!$E:$E,Z5,Taostats_CSV!H:H) -> 0 | AC5: =SUMIF(Taostats_CSV!$E:$E,Z5,Taostats_CSV!R:R) -> 0 | AD5: =SUMIFS($W:$W,$C:$C,$Z5,$S:$S,TRUE) -> 0 | AE5: =SUMIFS($X:$X,$E:$E,$Z5,$S:$S,TRUE) -> 0 | AF5: =SUMIFS($F:$F,$G:$G,$Z5,$S:$S,TRUE) -> 0 | AG5: =AD5+AF5-AA5 -> 0 | AH5: =AE5-AC5-AB5 -> 0
Z6: 0 | AA6: =SUMIF(Taostats_CSV!$E:$E,Z6,Taostats_CSV!G:G) -> 0 | AB6: =SUMIF(Taostats_CSV!$E:$E,Z6,Taostats_CSV!H:H) -> 0 | AC6: =SUMIF(Taostats_CSV!$E:$E,Z6,Taostats_CSV!R:R) -> 0 | AD6: =SUMIFS($W:$W,$C:$C,$Z6,$S:$S,TRUE) -> 0 | AE6: =SUMIFS($X:$X,$E:$E,$Z6,$S:$S,TRUE) -> 0 | AF6: =SUMIFS($F:$F,$G:$G,$Z6,$S:$S,TRUE) -> 0 | AG6: =AD6+AF6-AA6 -> 0 | AH6: =AE6-AC6-AB6 -> 0
AA7: =SUMIF(Taostats_CSV!$E:$E,Z7,Taostats_CSV!G:G) -> 0 | AB7: =SUMIF(Taostats_CSV!$E:$E,Z7,Taostats_CSV!H:H) -> 0 | AC7: =SUMIF(Taostats_CSV!$E:$E,Z7,Taostats_CSV!R:R) -> 0 | AD7: =SUMIFS($W:$W,$C:$C,$Z7,$S:$S,TRUE) -> 0 | AE7: =SUMIFS($X:$X,$E:$E,$Z7,$S:$S,TRUE) -> 0 | AF7: =SUMIFS($F:$F,$G:$G,$Z7,$S:$S,TRUE) -> 0 | AG7: =AD7+AF7-AA7 -> 0 | AH7: =AE7-AC7-AB7 -> 0
AA8: =SUMIF(Taostats_CSV!$E:$E,Z8,Taostats_CSV!G:G) -> 0 | AB8: =SUMIF(Taostats_CSV!$E:$E,Z8,Taostats_CSV!H:H) -> 0 | AC8: =SUMIF(Taostats_CSV!$E:$E,Z8,Taostats_CSV!R:R) -> 0 | AD8: =SUMIFS($W:$W,$C:$C,$Z8,$S:$S,TRUE) -> 0 | AE8: =SUMIFS($X:$X,$E:$E,$Z8,$S:$S,TRUE) -> 0 | AF8: =SUMIFS($F:$F,$G:$G,$Z8,$S:$S,TRUE) -> 0 | AG8: =AD8+AF8-AA8 -> 0 | AH8: =AE8-AC8-AB8 -> 0
AA9: =SUMIF(Taostats_CSV!$E:$E,Z9,Taostats_CSV!G:G) -> 0 | AB9: =SUMIF(Taostats_CSV!$E:$E,Z9,Taostats_CSV!H:H) -> 0 | AC9: =SUMIF(Taostats_CSV!$E:$E,Z9,Taostats_CSV!R:R) -> 0 | AD9: =SUMIFS($W:$W,$C:$C,$Z9,$S:$S,TRUE) -> 0 | AE9: =SUMIFS($X:$X,$E:$E,$Z9,$S:$S,TRUE) -> 0 | AF9: =SUMIFS($F:$F,$G:$G,$Z9,$S:$S,TRUE) -> 0 | AG9: =AD9+AF9-AA9 -> 0 | AH9: =AE9-AC9-AB9 -> 0
AA10: =SUMIF(Taostats_CSV!$E:$E,Z10,Taostats_CSV!G:G) -> 0 | AB10: =SUMIF(Taostats_CSV!$E:$E,Z10,Taostats_CSV!H:H) -> 0 | AC10: =SUMIF(Taostats_CSV!$E:$E,Z10,Taostats_CSV!R:R) -> 0 | AD10: =SUMIFS($W:$W,$C:$C,$Z10,$S:$S,TRUE) -> 0 | AE10: =SUMIFS($X:$X,$E:$E,$Z10,$S:$S,TRUE) -> 0 | AF10: =SUMIFS($F:$F,$G:$G,$Z10,$S:$S,TRUE) -> 0 | AG10: =AD10+AF10-AA10 -> 0 | AH10: =AE10-AC10-AB10 -> 0
AA11: =SUMIF(Taostats_CSV!$E:$E,Z11,Taostats_CSV!G:G) -> 0 | AB11: =SUMIF(Taostats_CSV!$E:$E,Z11,Taostats_CSV!H:H) -> 0 | AC11: =SUMIF(Taostats_CSV!$E:$E,Z11,Taostats_CSV!R:R) -> 0 | AD11: =SUMIFS($W:$W,$C:$C,$Z11,$S:$S,TRUE) -> 0 | AE11: =SUMIFS($X:$X,$E:$E,$Z11,$S:$S,TRUE) -> 0 | AF11: =SUMIFS($F:$F,$G:$G,$Z11,$S:$S,TRUE) -> 0 | AG11: =AD11+AF11-AA11 -> 0 | AH11: =AE11-AC11-AB11 -> 0
AA12: =SUMIF(Taostats_CSV!$E:$E,Z12,Taostats_CSV!G:G) -> 0 | AB12: =SUMIF(Taostats_CSV!$E:$E,Z12,Taostats_CSV!H:H) -> 0 | AC12: =SUMIF(Taostats_CSV!$E:$E,Z12,Taostats_CSV!R:R) -> 0 | AD12: =SUMIFS($W:$W,$C:$C,$Z12,$S:$S,TRUE) -> 0 | AE12: =SUMIFS($X:$X,$E:$E,$Z12,$S:$S,TRUE) -> 0 | AF12: =SUMIFS($F:$F,$G:$G,$Z12,$S:$S,TRUE) -> 0 | AG12: =AD12+AF12-AA12 -> 0 | AH12: =AE12-AC12-AB12 -> 0
AA13: =SUMIF(Taostats_CSV!$E:$E,Z13,Taostats_CSV!G:G) -> 0 | AB13: =SUMIF(Taostats_CSV!$E:$E,Z13,Taostats_CSV!H:H) -> 0 | AC13: =SUMIF(Taostats_CSV!$E:$E,Z13,Taostats_CSV!R:R) -> 0 | AD13: =SUMIFS($W:$W,$C:$C,$Z13,$S:$S,TRUE) -> 0 | AE13: =SUMIFS($X:$X,$E:$E,$Z13,$S:$S,TRUE) -> 0 | AF13: =SUMIFS($F:$F,$G:$G,$Z13,$S:$S,TRUE) -> 0 | AG13: =AD13+AF13-AA13 -> 0 | AH13: =AE13-AC13-AB13 -> 0
AA14: =SUMIF(Taostats_CSV!$E:$E,Z14,Taostats_CSV!G:G) -> 0 | AB14: =SUMIF(Taostats_CSV!$E:$E,Z14,Taostats_CSV!H:H) -> 0 | AC14: =SUMIF(Taostats_CSV!$E:$E,Z14,Taostats_CSV!R:R) -> 0 | AD14: =SUMIFS($W:$W,$C:$C,$Z14,$S:$S,TRUE) -> 0 | AE14: =SUMIFS($X:$X,$E:$E,$Z14,$S:$S,TRUE) -> 0 | AF14: =SUMIFS($F:$F,$G:$G,$Z14,$S:$S,TRUE) -> 0 | AG14: =AD14+AF14-AA14 -> 0 | AH14: =AE14-AC14-AB14 -> 0
AA15: =SUMIF(Taostats_CSV!$E:$E,Z15,Taostats_CSV!G:G) -> 0 | AB15: =SUMIF(Taostats_CSV!$E:$E,Z15,Taostats_CSV!H:H) -> 0 | AC15: =SUMIF(Taostats_CSV!$E:$E,Z15,Taostats_CSV!R:R) -> 0 | AD15: =SUMIFS($W:$W,$C:$C,$Z15,$S:$S,TRUE) -> 0 | AE15: =SUMIFS($X:$X,$E:$E,$Z15,$S:$S,TRUE) -> 0 | AF15: =SUMIFS($F:$F,$G:$G,$Z15,$S:$S,TRUE) -> 0 | AG15: =AD15+AF15-AA15 -> 0 | AH15: =AE15-AC15-AB15 -> 0
AA16: =SUMIF(Taostats_CSV!$E:$E,Z16,Taostats_CSV!G:G) -> 0 | AB16: =SUMIF(Taostats_CSV!$E:$E,Z16,Taostats_CSV!H:H) -> 0 | AC16: =SUMIF(Taostats_CSV!$E:$E,Z16,Taostats_CSV!R:R) -> 0 | AD16: =SUMIFS($W:$W,$C:$C,$Z16,$S:$S,TRUE) -> 0 | AE16: =SUMIFS($X:$X,$E:$E,$Z16,$S:$S,TRUE) -> 0 | AF16: =SUMIFS($F:$F,$G:$G,$Z16,$S:$S,TRUE) -> 0 | AG16: =AD16+AF16-AA16 -> 0 | AH16: =AE16-AC16-AB16 -> 0
AA17: =SUMIF(Taostats_CSV!$E:$E,Z17,Taostats_CSV!G:G) -> 0 | AB17: =SUMIF(Taostats_CSV!$E:$E,Z17,Taostats_CSV!H:H) -> 0 | AC17: =SUMIF(Taostats_CSV!$E:$E,Z17,Taostats_CSV!R:R) -> 0 | AD17: =SUMIFS($W:$W,$C:$C,$Z17,$S:$S,TRUE) -> 0 | AE17: =SUMIFS($X:$X,$E:$E,$Z17,$S:$S,TRUE) -> 0 | AF17: =SUMIFS($F:$F,$G:$G,$Z17,$S:$S,TRUE) -> 0 | AG17: =AD17+AF17-AA17 -> 0 | AH17: =AE17-AC17-AB17 -> 0
AA18: =SUMIF(Taostats_CSV!$E:$E,Z18,Taostats_CSV!G:G) -> 0 | AB18: =SUMIF(Taostats_CSV!$E:$E,Z18,Taostats_CSV!H:H) -> 0 | AC18: =SUMIF(Taostats_CSV!$E:$E,Z18,Taostats_CSV!R:R) -> 0 | AD18: =SUMIFS($W:$W,$C:$C,$Z18,$S:$S,TRUE) -> 0 | AE18: =SUMIFS($X:$X,$E:$E,$Z18,$S:$S,TRUE) -> 0 | AF18: =SUMIFS($F:$F,$G:$G,$Z18,$S:$S,TRUE) -> 0 | AG18: =AD18+AF18-AA18 -> 0 | AH18: =AE18-AC18-AB18 -> 0
... AA53: =SUMIF(Taostats_CSV!$E:$E,Z53,Taostats_CSV!G:G) -> 0 | AB53: =SUMIF(Taostats_CSV!$E:$E,Z53,Taostats_CSV!H:H) -> 0 | AC53: =SUMIF(Taostats_CSV!$E:$E,Z53,Taostats_CSV!R:R) -> 0 | AD53: =SUMIFS($W:$W,$C:$C,$Z53,$S:$S,TRUE) -> 0 | AE53: =SUMIFS($X:$X,$E:$E,$Z53,$S:$S,TRUE) -> 0 | AF53: =SUMIFS($F:$F,$G:$G,$Z53,$S:$S,TRUE) -> 0 | AG53: =AD53+AF53-AA53 -> 0 | AH53: =AE53-AC53-AB53 -> 0
AE158: =TYPE(Taostats_CSV!#REF!) -> 16
AE159: =TYPE(Taostats_CSV!#REF!) -> 16
AE160: =TYPE(Taostats_CSV!#REF!) -> 16

Sheet Cointracker Tags 2026-02-16
A1: Transaction | B1: Definition | C1: CoinTracker CSV tag
A2: Send | B2: You sent cryptocurrency to an external address that is not part of your own wallets. This may include personal payments, transfers to another person, or withdrawals to a wallet not added to CoinTracker.
A3: Receive | B3: You received cryptocurrency into your wallet from an external source. This may include incoming payments, gifts, or transfers from another person.
A4: Buy | B4: You acquired cryptocurrency using fiat currency (e.g., USD, EUR) through a centralized exchange, brokerage, or on-ramp service.
A5: Sell | B5: You disposed of cryptocurrency in exchange for fiat currency. This is typically logged when selling crypto on an exchange or converting it to cash.
A6: Transfer | B6: You moved crypto between wallets or exchanges you own. These are non-taxable by default and typically appear as paired send/receive transactions.
A7: Trade | B7: You exchanged one cryptocurrency for another (e.g., BTC → ETH). This category is commonly assigned to DEX trades and swaps.
A8: Staking transactions
A9: Staking reward | B9: You received rewards for staking assets. The Staking reward category can be applied to Receive transactions and the default tax treatment is taxable, however marking as non-taxable is a menu option. | C9: staking
A10: Stake | B10: You deposited assets into a liquid or illiquid staking contract and received a token in return. Applied to Trade or Mint (liquid) and Send (illiquid). Liquid defaults to taxable but can be marked non-taxable. Illiquid default is non-taxable. | C10: stake
A11: Unstake | B11: You redeemed staked assets by returning a staking token and withdrawing from a contract. Applied to Trade (liquid) and Receive (illiquid). Liquid is taxable but can be marked non-taxable. Illiquid is non-taxable by default. | C11: unstake
A12: Margin transactions
A13: Margin | B13: You traded assets through a margin order (separate from a spot trading wallet). | C13: margin
A14: Margin fee | B14: You paid a fee to cover interest or rollover fees on a margin loan. | C14: margin fee
A15: Margin gain | B15: You had a gain associated with a margin trade. | C15: margin gain
A16: Margin loss | B16: You had a loss associated with a margin trade. | C16: margin loss
A17: Margin rebate | B17: You received a rebate to adjust margin fees (the opposite of a margin fee). | C17: margin rebate
A18: Liquidity pool transactions
A19: Add liquidity | B19: You added assets to a liquidity pool and received an LP (liquidity provider) token in return. | C19: add_liquidity
A20: Remove liquidity | B20: You redeemed liquidity from a pool by returning an LP token. | C20: remove_liquidity
A21: Lending and borrowing transactions
A22: Borrow | B22: You borrowed assets from a lending contract, individual, or entity. | C22: borrow
A23: Loan repayment | B23: You returned borrowed funds. | C23: loan_repayment
A24: Lending deposit | B24: You deposited assets into a lending contract. | C24: lending_deposit
A25: Lending withdrawal | B25: You withdrew assets that had previously been deposited into a lending contract. | C25: lending_withdrawal
A26: Interest expense | B26: You paid the interest portion of a loan. | C26: interest_expense
A27: Interest | B27: You received income from lending your assets. | C27: interest
A28: Other transaction types
A29: Bridge | B29: You transferred assets to yourself on another chain. | C29: bridge
A30: Rebate | B30: You received a reward after making a purchase (e.g., cashback credit card reward). | C30: rebate
A31: Wrap | B31: You traded an asset for its wrapped or unwrapped version. | C31: wrap
A32: Mining reward | B32: You received a block reward as a validator or miner. | C32: mining
A33: Airdrop | B33: You received assets via an airdrop. | C33: airdrop
A34: Fork | B34: You received assets as the result of a blockchain fork. | C34: fork
A35: Payment | B35: You received crypto as payment for a good or service. | C35: payment
A36: Gambling income | B36: You received income from gambling. | C36: gambling_income
A37: Gambling expense | B37: You spent funds to place a bet. | C37: gambling_expense
A38: Other income | B38: You received income or rewards not categorized elsewhere (e.g., Coinbase Earn). | C38: other_income
A39: Gift | B39: You sent or received a gift. | C39: gift
A40: Donation | B40: You donated assets to a tax-exempt public charity. | C40: donation
...
